# Gilly's garden

weight=1
embed_into_distance=1
unacceptable_target_blocks=flowing_water,water,flowing_lava,lava
dimensions=5,7,9
max_leveling=2
leveling_buffer=0
preserve_water=0
preserve_lava=0
preserve_plants=0

rule1=0,100,grass
rule2=0,100,stonebrick
rule3=0,100,farmland
rule4=0,100,flowing_water
rule5=0,85,potatoes-2
rule6=0,85,carrots-2
rule7=0,85,wheat-2
rule8=0,100,reeds
rule9=0,100,fence
rule10=0,100,torch

layer
2,2,2,2,2,2,2,2,2
2,1,1,1,1,1,1,1,2
2,1,1,1,1,1,1,1,2
2,1,1,1,2,1,1,1,2
2,1,1,1,1,1,1,1,2
2,1,1,1,1,1,1,1,2
2,2,2,2,2,2,2,2,2
endlayer

layer
2,2,2,2,2,2,2,2,2
2,3,3,3,3,3,3,3,2
2,3,3,3,1,3,3,3,2
2,3,3,1,4,1,3,3,2
2,3,3,3,1,3,3,3,2
2,3,3,3,3,3,3,3,2
2,2,2,2,2,2,2,2,2
endlayer

layer
0,0,0,0,0,0,0,0,0
0,6,6,7,7,7,5,5,0
0,6,6,7,8,7,5,5,0
0,6,6,8,9,8,5,5,0
0,6,6,7,8,7,5,5,0
0,6,6,7,7,7,5,5,0
0,0,0,0,0,0,0,0,0
endlayer

layer
0,0,0,0,0,0,0,0,0
0,0,0,0,0,0,0,0,0
0,0,0,0,8,0,0,0,0
0,0,0,8,9,8,0,0,0
0,0,0,0,8,0,0,0,0
0,0,0,0,0,0,0,0,0
0,0,0,0,0,0,0,0,0
endlayer

layer
0,0,0,0,0,0,0,0,0
0,0,0,0,0,0,0,0,0
0,0,0,0,8,0,0,0,0
0,0,0,8,10,8,0,0,0
0,0,0,0,8,0,0,0,0
0,0,0,0,0,0,0,0,0
0,0,0,0,0,0,0,0,0
endlayer
