# Gilly's Reactor ControlRoom

# Uses Blocks from Chisel and Tinkers Construct

# template generated by Ruins mod version 14.6 Ingame Parser
# Structure created by Gilly

weight=1
embed_into_distance=31
acceptable_target_blocks=
unacceptable_target_blocks=flowing_water,water,flowing_lava,lava,ice,bedrock,netherrack,soul_sand,Natura:Cloud
dimensions=17,29,39
allowable_overhang=0
max_leveling=4
leveling_buffer=-1
preserve_water=0
preserve_lava=0

rule1=0,100,preserveBlock
rule2=0,100,minecraft:stained_hardened_clay-9
rule3=0,100,chisel:stonebricksmooth-12
rule4=0,100,minecraft:glowstone-0
rule5=0,100,minecraft:cauldron-0
rule6=0,100,minecraft:water-0
rule7=0,100,minecraft:stained_hardened_clay-4
rule8=0,100,chisel:technical-14
rule9=0,100,chisel:technical-13
rule10=0,100,chisel:technical-6
rule11=0,100,chisel:technical-15
rule12=0,100,chisel:technical-4
rule13=0,100,chisel:stonebricksmooth-10
rule14=0,100,chisel:technical-2
rule15=0,100,chisel:voidstone2-2
rule16=0,100,chisel:voidstone-2
rule17=0,100,chisel:tyrian-13
rule18=0,100,chisel:scorching-4
rule19=0,100,chisel:stained_glass_brown-13
rule20=0,100,chisel:autoChisel-0
rule21=0,100,minecraft:ladder-2
rule22=0,100,chisel:futura-0
rule23=0,100,chisel:factoryblock-5
rule24=0,100,chisel:factoryblock-13
rule25=0,100,chisel:tyrian-10
rule26=0,100,chisel:warningSign-0
rule27=0,100,chisel:glass-7
rule28=0,100,minecraft:iron_bars-0
rule29=0,100,chisel:glass-13
rule30=0,100,chisel:factoryblock-6
rule31=0,100,chisel:technical2-1
rule32=0,100,minecraft:stone_brick_stairs-0
rule33=0,100,chisel:cobblestone-10
rule34=0,100,minecraft:stone_brick_stairs-2
rule35=0,100,minecraft:stone_slab-0
rule36=0,100,minecraft:stone_brick_stairs-1
rule37=0,100,chisel:factoryblock-1
rule38=0,100,minecraft:ladder-3
rule39=0,100,minecraft:stone_brick_stairs-7
rule40=0,100,minecraft:stone_brick_stairs-6
rule41=0,100,minecraft:stone_brick_stairs-5
rule42=0,100,minecraft:stone_brick_stairs-4
rule43=0,100,chisel:factoryblock-4
rule44=0,100,minecraft:stained_hardened_clay-3
rule45=0,100,TConstruct:slime.pad-6
rule46=0,100,minecraft:double_stone_slab-8

layer
1,1,1,1,1,1,1,1,1,1,1,1,1,1,1,1,1,1,1,1,1,1,1,1,1,1,1,1,1,1,1,1,1,1,1,1,1,1,1
1,1,1,1,1,1,1,1,1,1,1,1,1,1,1,1,1,1,1,1,1,1,1,1,1,1,1,1,1,1,1,1,1,1,1,1,1,1,1
1,1,1,1,1,1,1,1,1,1,1,1,1,1,1,1,1,1,1,1,1,1,1,1,1,1,1,1,1,1,1,1,1,1,1,1,1,1,1
1,1,1,1,1,1,1,1,1,1,1,1,1,1,1,1,1,1,1,1,1,1,1,1,1,1,1,1,1,1,1,1,1,1,1,1,1,1,1
1,1,1,1,1,1,1,1,1,1,1,1,1,1,1,1,1,1,1,1,1,1,1,1,1,1,1,1,1,1,1,1,1,1,1,1,1,1,1
1,1,1,1,1,1,1,1,1,1,1,1,1,1,1,1,1,2,2,2,2,2,2,2,2,2,2,2,2,1,1,1,1,1,1,1,1,1,1
1,1,1,1,1,1,1,1,1,1,1,1,1,1,1,1,2,2,2,2,2,2,2,2,2,2,2,2,2,2,1,1,1,1,1,1,1,1,1
3,3,3,4,3,3,3,4,3,3,3,4,3,3,3,2,2,2,2,2,2,2,2,2,2,2,2,2,2,2,2,1,1,1,1,1,1,1,1
3,3,3,5,3,3,3,5,3,3,3,5,3,3,3,2,2,2,2,2,2,2,2,2,2,2,2,2,2,2,2,2,1,1,1,1,1,1,1
3,3,3,3,3,3,3,3,3,3,3,3,3,3,3,2,2,2,2,2,2,2,2,2,2,2,2,2,2,2,2,2,2,1,1,1,1,1,1
4,5,3,3,3,3,3,3,3,3,3,3,3,3,3,2,2,2,2,2,2,2,2,2,2,2,2,2,2,2,2,2,2,2,1,1,1,1,1
3,3,3,3,3,3,3,3,3,3,3,3,3,3,3,2,2,2,2,2,2,2,2,2,2,2,2,2,2,2,2,2,2,2,1,1,1,1,1
3,3,3,3,3,3,3,3,3,3,3,3,3,3,5,4,2,2,2,2,2,2,2,2,2,2,2,2,2,2,2,2,2,2,1,1,1,1,1
3,3,3,3,3,3,3,3,3,3,3,3,3,3,3,2,2,2,2,2,2,2,2,2,2,2,2,2,2,2,2,2,2,2,1,1,1,1,1
4,5,3,3,3,3,3,3,3,3,3,3,3,3,3,2,2,2,2,2,2,2,2,2,2,2,2,2,2,2,2,2,2,2,1,1,1,1,1
3,3,3,3,3,3,3,3,3,3,3,3,3,3,3,2,2,2,2,2,2,2,2,2,2,2,2,2,2,2,2,2,2,2,1,1,1,1,1
3,3,3,3,3,3,3,3,3,3,3,3,3,3,5,4,2,2,2,2,2,2,2,2,2,2,2,2,2,2,2,2,2,2,1,1,1,1,1
3,3,3,3,3,3,3,3,3,3,3,3,3,3,3,2,2,2,2,2,2,2,2,2,2,2,2,2,2,2,2,2,2,2,1,1,1,1,1
4,5,3,3,3,3,3,3,3,3,3,3,3,3,3,2,2,2,2,2,2,2,2,2,2,2,2,2,2,2,2,2,2,2,1,1,1,1,1
3,3,3,3,3,3,3,3,3,3,3,3,3,3,3,2,2,2,2,2,2,2,2,2,2,2,2,2,2,2,2,2,2,1,1,1,1,1,1
3,3,3,5,3,3,3,5,3,3,3,5,3,3,3,2,2,2,2,2,2,2,2,2,2,2,2,2,2,2,2,2,1,1,1,1,1,1,1
3,3,3,4,3,3,3,4,3,3,3,4,3,3,3,2,2,2,2,2,2,2,2,2,2,2,2,2,2,2,2,1,1,1,1,1,1,1,1
1,1,1,1,1,1,1,1,1,1,1,1,1,1,1,1,2,2,2,2,2,2,2,2,2,2,2,2,2,2,1,1,1,1,1,1,1,1,1
1,1,1,1,1,1,1,1,1,1,1,1,1,1,1,1,1,2,2,2,2,2,2,2,2,2,2,2,2,1,1,1,1,1,1,1,1,1,1
1,1,1,1,1,1,1,1,1,1,1,1,1,1,1,1,1,1,1,1,1,1,1,1,1,1,1,1,1,1,1,1,1,1,1,1,1,1,1
1,1,1,1,1,1,1,1,1,1,1,1,1,1,1,1,1,1,1,1,1,1,1,1,1,1,1,1,1,1,1,1,1,1,1,1,1,1,1
1,1,1,1,1,1,1,1,1,1,1,1,1,1,1,1,1,1,1,1,1,1,1,1,1,1,1,1,1,1,1,1,1,1,1,1,1,1,1
1,1,1,1,1,1,1,1,1,1,1,1,1,1,1,1,1,1,1,1,1,1,1,1,1,1,1,1,1,1,1,1,1,1,1,1,1,1,1
1,1,1,1,1,1,1,1,1,1,1,1,1,1,1,1,1,1,1,1,1,1,1,1,1,1,1,1,1,1,1,1,1,1,1,1,1,1,1
endlayer

layer
1,1,1,1,1,1,1,1,1,1,1,1,1,1,1,1,1,1,1,1,1,1,1,1,1,1,1,1,1,1,1,1,1,1,1,1,1,1,1
1,1,1,1,1,1,1,1,1,1,1,1,1,1,1,1,1,1,1,1,1,1,1,1,1,1,1,1,1,1,1,1,1,1,1,1,1,1,1
1,1,1,1,1,1,1,1,1,1,1,1,1,1,1,1,1,1,1,1,1,1,1,1,1,1,1,1,1,1,1,1,1,1,1,1,1,1,1
1,1,1,1,1,1,1,1,1,1,1,1,1,1,1,1,1,1,1,1,1,1,1,1,1,1,1,1,1,1,1,1,1,1,1,1,1,1,1
1,1,1,1,1,1,1,1,1,1,1,1,1,1,1,1,1,1,1,1,1,1,1,1,1,1,1,1,1,1,1,1,1,1,1,1,1,1,1
1,1,1,1,1,1,1,1,1,1,1,1,1,1,1,1,1,2,2,2,2,2,2,2,2,2,2,2,2,1,1,1,1,1,1,1,1,1,1
1,1,1,1,1,1,1,1,1,1,1,1,1,1,1,1,2,7,7,6,6,6,6,6,6,6,6,6,6,2,1,1,1,1,1,1,1,1,1
3,3,3,3,3,3,3,3,3,3,3,3,3,3,3,2,2,7,7,6,6,6,6,6,6,6,6,6,6,6,2,1,1,1,1,1,1,1,1
3,0,0,0,0,0,0,0,0,8,0,0,0,3,3,2,6,6,6,6,6,6,6,6,6,6,6,6,6,6,6,2,1,1,1,1,1,1,1
3,0,0,0,0,8,9,0,0,9,0,0,0,0,0,2,6,6,6,6,6,6,6,6,6,6,6,6,6,6,6,6,2,1,1,1,1,1,1
3,0,12,0,0,0,0,0,0,0,0,0,11,10,0,2,6,6,6,6,6,6,6,6,6,6,6,6,6,6,6,6,6,2,1,1,1,1,1
3,0,9,0,0,0,0,0,0,0,0,0,0,0,0,2,6,6,6,6,6,13,13,13,13,13,13,13,6,6,6,6,6,2,1,1,1,1,1
3,0,0,0,0,10,11,0,0,0,0,0,0,0,0,2,6,6,6,6,6,13,13,13,13,13,13,13,6,6,6,6,6,2,1,1,1,1,1
3,0,0,0,0,0,0,0,0,0,0,0,0,0,0,2,6,6,6,6,6,13,13,13,13,13,13,13,6,6,6,6,6,2,1,1,1,1,1
3,0,0,0,0,0,0,0,0,0,0,0,0,0,0,2,6,6,6,6,6,13,13,13,13,13,13,13,6,6,6,6,6,2,1,1,1,1,1
3,0,0,0,0,0,0,0,0,0,0,0,0,0,0,2,6,6,6,6,6,13,13,13,13,13,13,13,6,6,6,6,6,2,1,1,1,1,1
3,0,0,0,0,10,11,0,0,0,0,0,0,0,0,2,6,6,6,6,6,13,13,13,13,13,13,13,6,6,6,6,6,2,1,1,1,1,1
3,0,0,0,0,0,0,0,0,0,0,0,0,0,0,2,6,6,6,6,6,13,13,13,13,13,13,13,6,6,6,6,6,2,1,1,1,1,1
3,0,0,0,0,12,9,0,0,0,0,0,11,10,0,2,6,6,6,6,6,6,6,6,6,6,6,6,6,6,6,6,6,2,1,1,1,1,1
3,0,11,0,0,0,0,0,0,11,0,0,0,0,0,2,6,6,6,6,6,6,6,6,6,6,6,6,6,6,6,6,2,1,1,1,1,1,1
3,0,10,0,0,0,0,0,0,10,0,0,0,3,3,2,6,6,6,6,6,6,6,6,6,6,6,6,6,6,6,2,1,1,1,1,1,1,1
3,3,3,3,3,3,3,3,3,3,3,3,3,3,3,2,2,7,7,6,6,6,6,6,6,6,6,6,6,6,2,1,1,1,1,1,1,1,1
1,1,1,1,1,1,1,1,1,1,1,1,1,1,1,1,2,7,7,6,6,6,6,6,6,6,6,6,6,2,1,1,1,1,1,1,1,1,1
1,1,1,1,1,1,1,1,1,1,1,1,1,1,1,1,1,2,2,2,2,2,2,2,2,2,2,2,2,1,1,1,1,1,1,1,1,1,1
1,1,1,1,1,1,1,1,1,1,1,1,1,1,1,1,1,1,1,1,1,1,1,1,1,1,1,1,1,1,1,1,1,1,1,1,1,1,1
1,1,1,1,1,1,1,1,1,1,1,1,1,1,1,1,1,1,1,1,1,1,1,1,1,1,1,1,1,1,1,1,1,1,1,1,1,1,1
1,1,1,1,1,1,1,1,1,1,1,1,1,1,1,1,1,1,1,1,1,1,1,1,1,1,1,1,1,1,1,1,1,1,1,1,1,1,1
1,1,1,1,1,1,1,1,1,1,1,1,1,1,1,1,1,1,1,1,1,1,1,1,1,1,1,1,1,1,1,1,1,1,1,1,1,1,1
1,1,1,1,1,1,1,1,1,1,1,1,1,1,1,1,1,1,1,1,1,1,1,1,1,1,1,1,1,1,1,1,1,1,1,1,1,1,1
endlayer

layer
1,1,1,1,1,1,1,1,1,1,1,1,1,1,1,1,1,1,1,1,1,1,1,1,1,1,1,1,1,1,1,1,1,1,1,1,1,1,1
1,1,1,1,1,1,1,1,1,1,1,1,1,1,1,1,1,1,1,1,1,1,1,1,1,1,1,1,1,1,1,1,1,1,1,1,1,1,1
1,1,1,1,1,1,1,1,1,1,1,1,1,1,1,1,1,1,1,1,1,1,1,1,1,1,1,1,1,1,1,1,1,1,1,1,1,1,1
1,1,1,1,1,1,1,1,1,1,1,1,1,1,1,1,1,1,1,1,1,1,1,1,1,1,1,1,1,1,1,1,1,1,1,1,1,1,1
1,1,1,1,1,1,1,1,1,1,1,1,1,1,1,1,1,1,1,1,1,1,1,1,1,1,1,1,1,1,1,1,1,1,1,1,1,1,1
1,1,1,1,1,1,1,1,1,1,1,1,1,1,1,1,1,2,2,2,2,2,2,2,2,2,2,2,2,1,1,1,1,1,1,1,1,1,1
1,1,1,1,1,1,1,1,1,1,1,1,1,1,1,1,2,6,6,6,6,6,6,6,6,6,6,6,6,2,1,1,1,1,1,1,1,1,1
3,3,3,3,3,3,3,3,3,3,3,3,3,3,3,2,2,6,6,6,6,6,6,6,6,6,6,6,6,6,2,1,1,1,1,1,1,1,1
3,0,0,0,0,0,0,0,0,14,0,0,0,3,3,2,6,6,6,6,6,6,6,6,6,6,6,6,6,6,6,2,1,1,1,1,1,1,1
3,0,0,0,0,14,16,0,0,15,0,0,0,0,0,2,6,6,6,6,6,6,6,6,6,6,6,6,6,6,6,6,2,1,1,1,1,1,1
3,0,14,0,0,0,0,0,0,0,0,0,17,14,0,2,6,6,6,6,6,6,6,6,6,6,6,6,6,6,6,6,6,2,1,1,1,1,1
3,0,18,0,0,0,0,0,0,0,0,0,0,0,0,2,6,6,6,6,6,13,13,13,13,13,13,13,6,6,6,6,6,2,1,1,1,1,1
3,0,0,0,0,20,19,0,0,0,0,0,0,0,0,2,6,6,6,6,6,13,13,13,4,13,13,13,6,6,6,6,6,2,1,1,1,1,1
3,0,0,0,0,0,0,0,0,0,0,0,0,0,0,2,6,6,6,6,6,13,13,13,13,13,13,13,6,6,6,6,6,2,1,1,1,1,1
3,21,0,0,0,0,0,0,0,0,0,0,0,0,0,2,6,6,6,6,6,13,4,13,13,13,4,13,6,6,6,6,6,2,1,1,1,1,1
3,0,0,0,0,0,0,0,0,0,0,0,0,0,0,2,6,6,6,6,6,13,13,13,13,13,13,13,6,6,6,6,6,2,1,1,1,1,1
3,0,0,0,0,20,19,0,0,0,0,0,0,0,0,2,6,6,6,6,6,13,13,13,4,13,13,13,6,6,6,6,6,2,1,1,1,1,1
3,0,0,0,0,0,0,0,0,0,0,0,0,0,0,2,6,6,6,6,6,13,13,13,13,13,13,13,6,6,6,6,6,2,1,1,1,1,1
3,0,0,0,0,14,18,0,0,0,0,0,17,14,0,2,6,6,6,6,6,6,6,6,6,6,6,6,6,6,6,6,6,2,1,1,1,1,1
3,0,19,0,0,0,0,0,0,19,0,0,0,0,0,2,6,6,6,6,6,6,6,6,6,6,6,6,6,6,6,6,2,1,1,1,1,1,1
3,0,20,0,0,0,0,0,0,20,0,0,0,3,3,2,6,6,6,6,6,6,6,6,6,6,6,6,6,6,6,2,1,1,1,1,1,1,1
3,3,3,3,3,3,3,3,3,3,3,3,3,3,3,2,2,6,6,6,6,6,6,6,6,6,6,6,6,6,2,1,1,1,1,1,1,1,1
1,1,1,1,1,1,1,1,1,1,1,1,1,1,1,1,2,6,6,6,6,6,6,6,6,6,6,6,6,2,1,1,1,1,1,1,1,1,1
1,1,1,1,1,1,1,1,1,1,1,1,1,1,1,1,1,2,2,2,2,2,2,2,2,2,2,2,2,1,1,1,1,1,1,1,1,1,1
1,1,1,1,1,1,1,1,1,1,1,1,1,1,1,1,1,1,1,1,1,1,1,1,1,1,1,1,1,1,1,1,1,1,1,1,1,1,1
1,1,1,1,1,1,1,1,1,1,1,1,1,1,1,1,1,1,1,1,1,1,1,1,1,1,1,1,1,1,1,1,1,1,1,1,1,1,1
1,1,1,1,1,1,1,1,1,1,1,1,1,1,1,1,1,1,1,1,1,1,1,1,1,1,1,1,1,1,1,1,1,1,1,1,1,1,1
1,1,1,1,1,1,1,1,1,1,1,1,1,1,1,1,1,1,1,1,1,1,1,1,1,1,1,1,1,1,1,1,1,1,1,1,1,1,1
1,1,1,1,1,1,1,1,1,1,1,1,1,1,1,1,1,1,1,1,1,1,1,1,1,1,1,1,1,1,1,1,1,1,1,1,1,1,1
endlayer

layer
1,1,1,1,1,1,1,1,1,1,1,1,1,1,1,1,1,1,1,1,1,1,1,1,1,1,1,1,1,1,1,1,1,1,1,1,1,1,1
1,1,1,1,1,1,1,1,1,1,1,1,1,1,1,1,1,1,1,1,1,1,1,1,1,1,1,1,1,1,1,1,1,1,1,1,1,1,1
1,1,4,1,1,1,1,1,1,1,1,1,1,1,1,1,1,1,1,1,1,1,1,1,4,1,1,1,1,1,1,1,1,1,1,1,4,1,1
1,1,1,1,1,1,1,1,1,1,1,1,1,4,1,1,1,1,1,1,1,1,1,1,1,1,1,1,1,1,1,1,1,1,1,1,1,1,1
1,1,1,1,1,1,1,1,1,1,1,1,1,1,1,1,1,1,1,1,1,1,1,1,1,1,1,1,1,1,1,1,1,1,1,1,1,1,1
1,1,1,1,1,1,1,1,1,1,1,1,1,1,1,1,1,3,3,3,3,3,3,3,3,3,3,3,3,1,1,1,1,1,1,1,1,1,1
1,1,1,1,1,1,1,1,1,1,1,1,1,1,1,1,7,21,0,0,0,0,0,0,0,0,0,0,0,3,1,1,1,1,1,1,1,1,1
3,3,3,3,3,3,3,3,3,3,3,3,3,4,3,3,7,0,0,0,0,0,0,0,0,0,0,0,0,0,3,1,1,1,1,1,1,1,1
3,0,0,0,0,0,0,0,0,22,0,0,0,3,3,3,0,0,0,0,0,0,0,0,0,0,0,0,0,0,0,3,1,1,1,1,1,1,1
3,0,0,0,0,22,22,0,0,22,0,0,0,0,0,3,0,0,0,0,0,0,0,0,0,0,0,0,0,0,0,0,3,1,1,1,1,1,1
3,0,22,0,0,0,0,0,0,0,0,0,22,22,0,3,0,0,0,0,0,0,0,0,0,0,0,0,0,0,0,0,0,3,1,1,1,1,1
3,0,22,0,0,0,0,0,0,0,0,0,0,0,0,3,0,0,0,0,0,13,23,23,23,23,23,13,0,0,0,0,0,3,1,1,1,1,1
3,0,0,0,0,25,24,0,0,0,0,0,0,0,0,3,0,0,0,0,0,23,10,23,5,23,10,23,0,0,0,0,0,3,1,1,1,1,1
3,0,0,0,0,0,0,0,0,0,0,0,0,0,0,3,0,0,0,0,0,23,23,23,23,23,23,23,0,0,0,0,0,3,1,1,1,1,1
3,21,0,0,0,0,0,0,0,0,0,0,0,0,0,3,0,0,0,0,0,23,5,23,26,23,5,23,0,0,0,0,0,3,1,1,1,1,1
3,0,0,0,0,0,0,0,0,0,0,0,0,0,0,3,0,0,0,0,0,23,23,23,23,23,23,23,0,0,0,0,0,3,1,1,1,1,1
3,0,0,0,0,25,24,0,0,0,0,0,0,0,0,3,0,0,0,0,0,23,10,23,5,23,10,23,0,0,0,0,0,3,1,1,1,1,1
3,0,0,0,0,0,0,0,0,0,0,0,0,0,0,3,0,0,0,0,0,13,23,23,23,23,23,13,0,0,0,0,0,3,1,1,1,1,1
3,0,0,0,0,22,22,0,0,0,0,0,22,22,0,3,0,0,0,0,0,0,0,0,0,0,0,0,0,0,0,0,0,3,1,1,1,1,1
3,0,24,0,0,0,0,0,0,24,0,0,0,0,0,3,0,0,0,0,0,0,0,0,0,0,0,0,0,0,0,0,3,1,1,1,1,1,1
3,0,25,0,0,0,0,0,0,25,0,0,0,3,3,3,0,0,0,0,0,0,0,0,0,0,0,0,0,0,0,3,1,1,1,1,1,1,1
3,3,3,3,3,3,3,3,3,3,3,3,3,4,3,3,7,0,0,0,0,0,0,0,0,0,0,0,0,0,3,1,1,1,1,1,1,1,1
1,1,1,1,1,1,1,1,1,1,1,1,1,1,1,1,7,21,0,0,0,0,0,0,0,0,0,0,0,3,1,1,1,1,1,1,1,1,1
1,1,1,1,1,1,1,1,1,1,1,1,1,1,1,1,1,3,3,3,3,3,3,3,3,3,3,3,3,1,1,1,1,1,1,1,1,1,1
1,1,1,1,1,1,1,1,1,1,1,1,1,1,1,1,1,1,1,1,1,1,1,1,1,1,1,1,1,1,1,1,1,1,1,1,1,1,1
1,1,1,1,1,1,1,1,1,1,1,1,1,4,1,1,1,1,1,1,1,1,1,1,1,1,1,1,1,1,1,1,1,1,1,1,1,1,1
1,1,4,1,1,1,1,1,1,1,1,1,1,1,1,1,1,1,1,1,1,1,1,1,4,1,1,1,1,1,1,1,1,1,1,1,4,1,1
1,1,1,1,1,1,1,1,1,1,1,1,1,1,1,1,1,1,1,1,1,1,1,1,1,1,1,1,1,1,1,1,1,1,1,1,1,1,1
1,1,1,1,1,1,1,1,1,1,1,1,1,1,1,1,1,1,1,1,1,1,1,1,1,1,1,1,1,1,1,1,1,1,1,1,1,1,1
endlayer

layer
2,2,2,2,2,2,2,2,2,2,2,2,2,2,2,2,2,2,2,2,2,2,2,2,2,2,2,2,2,2,2,2,2,2,2,2,2,2,2
2,3,3,3,3,3,3,3,3,3,3,3,3,3,3,3,3,3,3,3,3,3,3,3,3,3,3,3,3,3,3,3,3,3,3,3,3,3,2
2,3,27,3,3,3,3,3,3,3,3,3,3,3,3,3,3,3,3,3,3,3,3,3,27,3,3,3,3,3,3,3,3,3,3,3,27,3,2
2,3,3,2,2,2,2,2,2,2,2,2,3,27,3,3,2,2,2,2,2,2,2,2,3,2,2,2,2,2,2,2,2,2,2,2,3,3,2
2,3,3,2,1,1,1,1,1,1,2,2,3,3,3,3,2,2,2,2,2,2,2,2,3,2,2,2,2,2,1,1,1,1,1,2,3,3,2
2,3,3,2,1,1,1,1,1,1,2,2,3,3,3,3,7,3,3,3,3,3,3,3,3,3,3,3,3,2,1,1,1,1,1,2,3,3,2
2,3,3,2,1,1,1,1,1,1,2,2,3,3,3,3,30,21,0,0,0,0,0,28,29,28,0,0,0,3,1,1,1,1,1,2,3,3,2
2,3,3,3,2,2,2,2,2,2,2,2,3,27,3,3,30,0,0,0,0,0,0,28,29,28,0,0,0,0,3,1,1,1,1,2,3,3,2
2,3,3,3,3,3,3,3,3,3,3,3,3,3,3,3,0,0,0,0,0,0,0,28,29,28,0,0,0,0,0,3,1,1,1,2,3,3,2
2,3,3,3,3,3,3,3,3,3,3,3,3,3,3,3,0,0,0,0,0,28,28,28,29,28,28,28,0,0,0,0,3,1,1,2,3,3,2
2,3,3,3,3,3,3,3,3,0,0,3,3,3,3,3,0,0,0,0,28,28,30,30,30,30,30,28,28,0,0,0,0,3,2,2,3,3,2
2,3,3,3,28,3,3,3,3,0,0,3,3,4,3,3,0,0,0,28,28,30,0,0,0,0,0,30,28,28,0,0,0,3,2,2,3,3,2
2,3,3,3,3,3,3,3,3,3,3,3,3,3,3,3,0,0,0,28,30,0,0,0,0,0,0,0,30,28,0,0,0,3,2,2,3,3,2
2,3,3,3,3,3,3,3,3,3,3,3,0,0,0,3,28,28,28,28,30,0,0,0,0,0,0,0,30,28,0,0,0,3,2,2,3,3,2
2,29,29,3,3,3,28,3,3,3,4,3,0,0,0,3,29,29,29,29,30,0,0,0,0,0,0,0,30,28,0,0,0,3,2,2,3,3,2
2,3,3,3,3,3,3,3,3,3,3,3,0,0,0,3,28,28,28,28,30,0,0,0,0,0,0,0,30,28,0,0,0,3,2,2,3,3,2
2,3,3,3,3,3,3,3,3,3,3,3,3,3,3,3,0,0,0,28,30,0,0,0,0,0,0,0,30,28,0,0,0,3,2,2,3,3,2
2,3,3,3,28,3,3,3,3,3,3,3,3,4,3,3,0,0,0,28,28,30,0,0,0,0,0,30,28,28,0,0,0,3,2,2,3,3,2
2,3,3,3,3,3,3,3,3,3,3,3,3,3,3,3,0,0,0,0,28,28,30,30,30,30,30,28,28,0,0,0,0,3,2,2,3,3,2
2,3,3,3,3,3,3,3,3,3,3,3,3,3,3,3,0,0,0,0,0,28,28,28,29,28,28,28,0,0,0,0,3,1,1,2,3,3,2
2,3,3,3,3,3,3,3,3,3,3,3,3,3,3,3,0,0,0,0,0,0,0,28,29,28,0,0,0,0,0,3,1,1,1,2,3,3,2
2,3,3,3,3,3,3,2,2,2,2,2,3,27,3,3,30,0,0,0,0,0,0,28,29,28,0,0,0,0,3,1,1,1,1,2,3,3,2
2,3,3,2,1,1,1,2,2,2,2,2,3,3,3,3,30,21,0,0,0,0,0,28,29,28,0,0,0,3,1,1,1,1,1,2,3,3,2
2,3,3,2,1,1,1,2,2,2,2,2,3,3,3,3,7,3,3,3,3,3,3,3,3,3,3,3,3,2,1,1,1,1,1,2,3,3,2
2,3,3,2,1,1,1,2,2,2,2,2,3,3,3,3,2,2,2,2,2,2,2,2,3,2,2,2,2,2,1,1,1,1,1,2,3,3,2
2,3,3,2,2,2,2,2,2,2,2,2,3,27,3,3,2,2,2,2,2,2,2,2,3,2,2,2,2,2,2,2,2,2,2,2,3,3,2
2,3,27,3,3,3,3,3,3,3,3,3,3,3,3,3,3,3,3,3,3,3,3,3,27,3,3,3,3,3,3,3,3,3,3,3,27,3,2
2,3,3,3,3,3,3,3,3,3,3,3,3,3,3,3,3,3,3,3,3,3,3,3,3,3,3,3,3,3,3,3,3,3,3,3,3,3,2
2,2,2,2,2,2,2,2,2,2,2,2,2,2,2,2,2,2,2,2,2,2,2,2,2,2,2,2,2,2,2,2,2,2,2,2,2,2,2
endlayer

layer
2,2,2,2,2,2,2,2,2,2,2,2,2,2,2,2,2,2,2,2,2,2,2,2,2,2,2,2,2,2,2,2,2,2,2,2,2,2,2
2,0,0,0,0,0,0,0,0,0,0,0,0,0,0,0,0,0,0,0,0,0,0,0,0,0,0,0,0,0,0,0,0,0,0,0,0,0,2
2,0,0,0,0,0,0,0,0,0,0,0,0,0,0,0,0,0,0,0,0,0,0,0,0,0,0,0,0,0,0,0,0,0,0,0,0,0,2
2,0,0,2,2,2,31,2,2,2,2,2,0,0,0,0,2,31,2,2,2,31,2,2,0,2,31,2,2,2,2,31,2,2,2,2,0,0,2
2,0,0,2,1,1,1,1,1,1,2,2,0,0,0,0,2,2,2,2,2,2,2,3,0,3,2,2,2,2,1,1,1,1,1,2,0,0,2
2,0,0,2,1,1,1,1,1,1,2,2,0,0,0,0,7,3,3,3,3,3,3,3,0,3,3,3,3,2,1,1,1,1,1,2,0,0,2
2,0,0,2,1,1,1,1,1,1,2,2,0,0,0,0,0,0,0,0,0,0,0,0,0,0,0,0,0,3,1,1,1,1,1,2,0,0,2
2,0,0,31,1,1,1,2,2,2,2,2,0,0,0,0,7,0,0,0,0,0,0,0,0,0,0,0,0,0,3,1,1,1,1,31,0,0,2
2,0,0,2,2,2,2,2,2,2,2,2,0,0,0,0,30,0,0,0,0,0,0,0,0,0,0,0,0,0,0,3,1,1,1,2,0,0,2
2,0,0,2,2,2,2,2,2,2,33,33,32,32,32,32,30,0,0,0,0,0,0,0,0,0,0,0,0,0,0,0,3,1,1,2,0,0,2
2,0,0,2,2,2,2,2,2,29,29,33,33,33,33,33,30,0,0,0,0,0,0,0,0,0,0,0,0,0,0,0,0,3,2,2,0,0,2
2,0,0,2,4,2,2,2,33,29,29,33,33,27,33,33,30,0,0,0,0,0,0,0,0,0,0,0,0,0,0,0,0,3,2,2,0,0,2
2,0,0,31,2,2,2,2,33,33,33,33,33,33,33,33,30,0,0,0,0,0,0,0,0,0,0,0,0,0,0,0,0,3,2,31,0,0,2
2,0,0,2,2,2,2,2,33,33,33,33,29,29,29,34,0,0,0,0,0,0,0,0,0,0,0,0,0,0,0,0,0,3,2,2,0,0,2
2,0,0,2,2,2,4,2,33,33,27,33,29,29,29,34,0,0,0,0,0,0,0,0,0,0,0,0,0,0,0,0,0,3,2,2,0,0,2
2,0,0,2,2,2,2,2,33,33,33,33,29,29,29,34,0,0,0,0,0,0,0,0,0,0,0,0,0,0,0,0,0,3,2,2,0,0,2
2,0,0,31,2,2,2,2,33,33,33,33,33,33,33,33,30,0,0,0,0,0,0,0,0,0,0,0,0,0,0,0,0,3,2,31,0,0,2
2,0,0,2,4,2,2,2,33,33,33,33,33,27,33,33,30,0,0,0,0,0,0,0,0,0,0,0,0,0,0,0,0,3,2,2,0,0,2
2,0,0,2,2,2,2,2,35,35,35,35,33,33,33,33,30,0,0,0,0,0,0,0,0,0,0,0,0,0,0,0,0,3,2,2,0,0,2
2,0,0,2,2,2,2,2,35,6,6,35,33,33,33,33,30,0,0,0,0,0,0,0,0,0,0,0,0,0,0,0,3,1,1,2,0,0,2
2,0,0,2,2,2,2,2,37,6,6,37,36,36,36,36,30,0,0,0,0,0,0,0,0,0,0,0,0,0,0,3,1,1,1,2,0,0,2
2,0,0,31,1,1,1,2,2,2,2,2,0,0,0,0,7,0,0,0,0,0,0,0,0,0,0,0,0,0,3,1,1,1,1,31,0,0,2
2,0,0,2,1,1,1,2,2,2,2,2,0,0,0,0,0,0,0,0,0,0,0,0,0,0,0,0,0,3,1,1,1,1,1,2,0,0,2
2,0,0,2,1,1,1,2,2,2,2,2,0,0,0,0,7,3,3,3,3,3,3,3,0,3,3,3,3,2,1,1,1,1,1,2,0,0,2
2,0,0,2,1,1,1,2,2,2,2,2,0,0,0,0,2,2,2,2,2,2,2,3,0,3,2,2,2,2,1,1,1,1,1,2,0,0,2
2,0,0,2,2,2,31,2,2,2,31,2,0,0,0,0,2,31,2,2,2,31,2,2,0,2,31,2,2,2,2,31,2,2,2,2,0,0,2
2,0,0,0,0,0,0,0,0,0,0,0,0,0,0,0,0,0,0,0,0,0,0,0,0,0,0,0,0,0,0,0,0,0,0,0,0,0,2
2,0,0,0,0,0,0,0,0,0,0,0,0,0,0,0,0,0,0,0,0,0,0,0,0,0,0,0,0,0,0,0,0,0,0,0,0,0,2
2,2,2,2,2,2,2,2,2,2,2,2,2,2,2,2,2,2,2,2,2,2,2,2,2,2,2,2,2,2,2,2,2,2,2,2,2,2,2
endlayer

layer
7,7,7,7,7,7,7,7,7,7,7,7,7,7,7,7,7,7,7,7,7,7,7,7,7,7,7,7,7,7,7,7,7,7,7,7,7,7,7
7,0,0,0,0,0,0,0,0,0,0,0,0,0,0,0,0,0,0,0,0,0,0,0,0,0,0,0,0,0,0,0,0,0,0,0,0,0,7
7,0,0,0,0,0,0,0,0,0,0,0,0,0,0,0,0,0,0,0,0,0,0,0,0,0,0,0,0,0,0,0,0,0,0,0,0,0,7
7,0,0,7,7,7,7,7,7,7,7,7,0,0,0,0,7,7,7,7,7,7,7,7,0,7,7,7,7,7,7,7,7,7,7,7,0,0,7
7,0,0,7,1,1,1,1,1,1,2,7,0,0,0,0,7,2,2,2,2,0,2,3,0,3,0,2,2,2,1,1,1,1,1,7,0,0,7
7,0,0,7,1,1,1,1,1,1,2,7,0,0,0,0,7,3,12,3,3,28,3,3,0,3,28,3,3,2,1,1,1,1,1,7,0,0,7
7,0,0,7,1,1,1,1,1,1,2,7,0,0,0,0,0,0,0,0,0,0,0,0,0,0,0,0,0,3,1,1,1,1,1,7,0,0,7
7,0,0,7,1,1,1,2,2,2,2,7,0,0,0,0,7,0,0,0,0,0,0,0,0,0,0,0,0,0,3,1,1,1,1,7,0,0,7
7,0,0,7,2,2,2,2,2,2,2,7,0,0,0,0,0,0,0,0,0,0,0,0,0,0,0,0,0,0,0,3,1,1,1,7,0,0,7
7,0,0,7,2,2,2,2,2,2,0,0,0,0,0,0,0,0,0,0,0,0,0,0,0,0,0,0,0,0,0,0,3,1,1,7,0,0,7
7,0,0,7,2,2,2,2,2,0,0,0,0,0,0,0,0,0,0,0,0,0,0,0,0,0,0,0,0,0,0,0,0,3,2,7,0,0,7
7,0,0,7,2,2,2,2,0,0,0,0,0,0,0,0,0,0,0,0,0,0,0,0,0,0,0,0,0,0,0,0,0,3,2,7,0,0,7
7,0,0,7,2,2,2,34,0,0,0,0,0,0,0,0,0,0,0,0,0,0,0,0,0,0,0,0,0,0,0,0,0,28,0,7,0,0,7
7,0,0,7,2,2,2,34,0,0,0,0,0,0,0,0,0,0,0,0,0,0,0,0,0,0,0,0,0,0,0,0,0,3,2,7,0,0,7
7,0,0,7,2,2,2,34,0,0,0,0,0,0,0,0,0,0,0,0,0,0,0,0,0,0,0,0,0,0,0,0,0,8,2,7,0,0,7
7,0,0,7,2,2,2,34,0,0,0,0,0,0,0,0,0,0,0,0,0,0,0,0,0,0,0,0,0,0,0,0,0,3,2,7,0,0,7
7,0,0,7,2,2,2,34,0,0,0,0,0,0,0,0,0,0,0,0,0,0,0,0,0,0,0,0,0,0,0,0,0,28,0,7,0,0,7
7,0,0,7,2,2,2,2,0,0,0,0,0,0,0,0,0,0,0,0,0,0,0,0,0,0,0,0,0,0,0,0,0,3,2,7,0,0,7
7,0,0,7,2,7,2,2,0,0,0,0,0,0,0,0,0,0,0,0,0,0,0,0,0,0,0,0,0,0,0,0,0,3,2,7,0,0,7
7,0,0,7,2,7,2,2,0,0,0,0,0,0,0,0,0,0,0,0,0,0,0,0,0,0,0,0,0,0,0,0,3,1,1,7,0,0,7
7,0,0,7,2,7,7,2,37,21,38,37,0,0,0,0,0,0,0,0,0,0,0,0,0,0,0,0,0,0,0,3,1,1,1,7,0,0,7
7,0,0,7,2,2,2,2,2,2,2,7,0,0,0,0,7,0,0,0,0,0,0,0,0,0,0,0,0,0,3,1,1,1,1,7,0,0,7
7,0,0,7,1,1,1,2,2,2,2,7,0,0,0,0,0,0,0,0,0,0,0,0,0,0,0,0,0,3,1,1,1,1,1,7,0,0,7
7,0,0,7,1,1,1,2,2,2,2,7,0,0,0,0,7,3,10,3,3,28,3,3,0,3,28,3,3,2,1,1,1,1,1,7,0,0,7
7,0,0,7,1,1,1,2,2,2,2,7,0,0,0,0,7,2,2,2,2,0,2,3,0,3,0,2,2,2,1,1,1,1,1,7,0,0,7
7,0,0,7,7,7,7,7,7,7,7,7,0,0,0,0,7,7,7,7,7,7,7,7,0,7,7,7,7,7,7,7,7,7,7,7,0,0,7
7,0,0,0,0,0,0,0,0,0,0,0,0,0,0,0,0,0,0,0,0,0,0,0,0,0,0,0,0,0,0,0,0,0,0,0,0,0,7
7,0,0,0,0,0,0,0,0,0,0,0,0,0,0,0,0,0,0,0,0,0,0,0,0,0,0,0,0,0,0,0,0,0,0,0,0,0,7
7,7,7,7,7,7,7,7,7,7,7,7,7,7,7,7,7,7,7,7,7,7,7,7,7,7,7,7,7,7,7,7,7,7,7,7,7,7,7
endlayer

layer
2,2,2,2,2,2,2,2,2,2,2,2,2,2,2,2,2,2,2,2,2,2,2,2,2,2,2,2,2,2,2,2,2,2,2,2,2,2,2
2,0,0,0,0,0,0,0,0,0,0,0,0,0,0,0,0,0,0,0,0,0,0,0,0,0,0,0,0,0,0,0,0,0,0,0,0,0,2
2,0,0,0,0,0,0,0,0,0,0,0,0,0,0,0,0,0,0,0,0,0,0,0,0,0,0,0,0,0,0,0,0,0,0,0,0,0,2
2,0,0,2,2,2,28,2,2,2,28,2,40,0,0,39,2,28,2,2,2,28,2,2,0,2,28,2,2,2,2,28,2,2,2,2,0,0,2
2,0,0,2,2,2,4,2,2,2,0,4,2,0,0,2,4,0,2,2,2,4,2,3,0,3,4,2,2,2,2,4,2,2,2,2,0,0,2
2,0,0,2,2,2,2,2,2,2,2,2,40,0,0,39,2,2,2,2,2,2,2,3,0,3,2,2,2,2,2,2,2,2,2,2,0,0,2
2,0,0,2,2,2,2,2,2,2,2,2,0,0,0,0,0,39,2,2,2,2,2,0,0,0,2,2,2,2,2,2,2,2,2,2,0,0,2
2,0,0,28,4,2,2,2,2,2,2,2,0,0,0,0,26,3,3,3,3,3,3,3,26,3,3,3,3,2,2,4,2,2,4,28,0,0,2
2,0,0,2,2,2,2,2,4,2,2,7,0,0,0,0,0,0,0,0,0,0,0,0,0,0,0,0,0,3,2,2,2,2,2,2,0,0,2
2,0,0,2,2,2,2,2,2,2,0,0,0,0,0,0,0,0,0,0,0,0,0,0,0,0,0,0,0,0,3,2,2,2,2,2,0,0,2
2,0,0,2,2,2,2,2,2,0,0,0,0,0,0,0,0,0,0,0,0,0,0,0,0,0,0,0,0,0,0,3,2,2,2,2,0,0,2
2,0,0,2,2,2,2,2,0,0,0,0,0,0,0,0,0,0,0,0,0,0,0,0,0,0,0,0,0,0,0,3,2,2,2,2,0,0,2
2,0,0,28,4,2,34,0,0,0,0,0,0,0,0,0,0,0,0,0,0,0,0,0,0,0,0,0,0,0,0,3,2,2,4,28,0,0,2
2,0,0,2,2,2,34,0,0,0,0,0,0,0,0,0,0,0,0,0,0,0,0,0,0,0,0,0,0,0,0,3,2,2,2,2,0,0,2
2,0,0,2,2,2,34,0,0,0,0,0,0,0,0,0,0,0,0,0,0,0,0,0,0,0,0,0,0,0,0,26,2,2,2,2,0,0,2
2,0,0,2,2,2,34,0,0,0,0,0,0,0,0,0,0,0,0,0,0,0,0,0,0,0,0,0,0,0,0,3,2,2,2,2,0,0,2
2,0,0,28,4,2,34,0,0,0,0,0,0,0,0,0,0,0,0,0,0,0,0,0,0,0,0,0,0,0,0,3,2,2,4,28,0,0,2
2,0,0,2,2,2,2,2,0,0,0,0,0,0,0,0,0,0,0,0,0,0,0,0,0,0,0,0,0,0,0,3,2,2,2,2,0,0,2
2,0,0,2,2,2,2,2,0,0,0,0,0,0,0,0,0,0,0,0,0,0,0,0,0,0,0,0,0,0,0,3,2,2,2,2,0,0,2
2,0,0,2,2,2,2,2,0,0,0,0,0,0,0,0,0,0,0,0,0,0,0,0,0,0,0,0,0,0,3,2,2,2,2,2,0,0,2
2,0,0,2,2,2,2,2,37,21,38,37,0,0,0,0,0,0,0,0,0,0,0,0,0,0,0,0,0,3,2,2,2,2,2,2,0,0,2
2,0,0,28,4,2,2,2,2,2,2,7,0,0,0,0,26,3,3,3,3,3,3,3,26,3,3,3,3,2,2,4,2,2,4,28,0,0,2
2,0,0,2,2,2,2,2,2,2,2,2,0,0,0,0,0,39,2,2,2,2,2,0,0,0,2,2,2,2,2,2,2,2,2,2,0,0,2
2,0,0,2,2,2,2,2,2,2,2,2,40,0,0,39,2,2,2,2,2,2,2,3,0,3,2,2,2,2,2,2,2,2,2,2,0,0,2
2,0,0,2,2,2,4,2,2,2,0,4,2,0,0,2,4,0,2,2,2,4,2,3,0,3,4,2,2,2,2,4,2,2,2,2,0,0,2
2,0,0,2,2,2,28,2,2,2,28,2,40,0,0,39,2,28,2,2,2,28,2,2,0,2,28,2,2,2,2,28,2,2,2,2,0,0,2
2,0,0,0,0,0,0,0,0,0,0,0,0,0,0,0,0,0,0,0,0,0,0,0,0,0,0,0,0,0,0,0,0,0,0,0,0,0,2
2,0,0,0,0,0,0,0,0,0,0,0,0,0,0,0,0,0,0,0,0,0,0,0,0,0,0,0,0,0,0,0,0,0,0,0,0,0,2
2,2,2,2,2,2,2,2,2,2,2,2,2,2,2,2,2,2,2,2,2,2,2,2,2,2,2,2,2,2,2,2,2,2,2,2,2,2,2
endlayer

layer
1,1,1,1,1,1,2,2,2,2,2,2,2,2,2,2,2,2,2,2,2,2,2,2,2,2,2,2,2,2,2,2,1,1,1,1,1,1,1
1,2,2,2,2,2,2,2,29,2,2,2,29,2,29,2,2,2,29,2,29,2,2,2,29,2,29,2,2,2,29,2,2,2,2,2,2,2,1
1,2,2,2,2,2,2,2,29,2,2,2,29,2,29,2,2,2,29,2,29,2,2,2,29,2,29,2,2,2,29,2,2,2,2,2,2,2,1
1,2,2,2,2,2,2,2,2,2,2,2,2,2,2,2,2,2,2,2,2,2,2,2,2,2,2,2,2,2,2,2,2,2,2,2,2,2,1
1,2,2,2,2,2,27,2,2,2,2,27,2,2,2,2,27,2,2,2,2,27,2,2,2,2,27,2,2,2,2,27,2,2,2,2,2,2,1
1,2,2,2,2,2,2,2,2,2,2,2,2,2,2,2,2,2,2,2,2,2,2,2,2,2,2,2,2,2,2,2,2,2,2,2,2,2,1
2,2,2,2,2,2,2,2,2,2,2,2,2,2,2,2,2,2,2,2,2,2,2,2,2,2,2,2,2,2,2,2,2,2,2,2,2,2,2
2,29,29,2,27,2,2,2,2,2,2,2,41,41,41,41,30,30,30,30,30,30,30,30,30,30,30,30,30,2,2,27,2,2,27,2,29,29,2
2,2,2,2,2,2,2,2,27,2,30,30,0,0,0,0,0,28,29,28,0,0,0,0,0,0,0,0,0,30,2,2,2,2,2,2,2,2,2
2,2,2,2,2,2,2,2,2,30,0,0,0,0,0,0,0,28,29,28,0,0,0,0,0,0,0,0,0,0,30,2,2,2,2,2,2,2,2
2,29,29,2,2,2,2,2,30,0,0,0,0,0,0,0,0,28,29,28,0,0,0,0,0,0,0,0,0,0,0,30,2,2,2,2,29,29,2
2,2,2,2,2,36,36,26,0,0,0,0,0,0,0,0,0,28,29,28,0,0,0,0,0,0,0,0,0,0,0,30,2,2,2,2,2,2,2
2,29,29,2,27,34,0,0,0,0,0,0,0,0,0,0,0,28,29,28,0,0,0,0,0,0,0,0,0,0,0,30,2,2,27,2,29,29,2
2,2,2,2,2,34,0,0,0,0,0,0,0,0,0,0,0,28,29,28,0,0,0,0,0,0,0,0,0,0,0,30,2,2,2,2,2,2,2
2,2,2,2,2,34,0,0,0,0,0,0,0,0,0,0,0,28,18,28,0,0,0,0,0,0,0,0,0,0,0,30,2,2,2,2,2,2,2
2,2,2,2,2,34,0,0,0,0,0,0,0,0,0,0,0,28,29,28,0,0,0,0,0,0,0,0,0,0,0,30,2,2,2,2,2,2,2
2,29,29,2,27,34,0,0,0,0,0,0,0,0,0,0,0,28,29,28,0,0,0,0,0,0,0,0,0,0,0,30,2,2,27,2,29,29,2
2,2,2,2,2,32,32,26,0,0,0,0,0,0,0,0,0,28,29,28,0,0,0,0,0,0,0,0,0,0,0,30,2,2,2,2,2,2,2
2,29,29,2,2,2,2,30,0,0,0,0,0,0,0,0,0,28,29,28,0,0,0,0,0,0,0,0,0,0,0,30,2,2,2,2,29,29,2
2,2,2,2,2,2,2,30,28,28,28,28,0,0,0,0,0,28,29,28,0,0,0,0,0,0,0,0,0,0,30,2,2,2,2,2,2,2,2
2,2,2,2,2,2,2,30,37,21,38,37,0,0,0,0,0,28,29,28,0,0,0,0,0,0,0,0,0,30,2,2,2,2,2,2,2,2,2
2,29,29,2,27,2,2,30,30,30,30,30,42,42,42,42,30,30,30,30,30,30,30,30,30,30,30,30,30,2,2,27,2,2,27,2,29,29,2
2,2,2,2,2,2,2,2,2,2,2,2,2,2,2,2,2,2,2,2,2,2,2,2,2,2,2,2,2,2,2,2,2,2,2,2,2,2,2
1,2,2,30,30,30,2,2,2,2,2,2,2,2,2,2,2,2,2,2,2,2,2,2,2,2,2,2,2,2,2,2,2,2,2,2,2,2,1
1,2,2,13,13,13,27,2,2,2,2,27,2,2,2,2,27,2,2,2,2,27,2,2,2,2,27,2,2,2,2,27,2,2,2,2,2,2,1
1,2,2,13,43,13,2,2,2,2,2,2,2,2,2,2,2,2,2,2,2,2,2,2,2,2,2,2,2,2,2,2,2,2,2,2,2,2,1
1,2,2,13,13,13,2,2,29,2,2,2,29,2,29,2,2,2,29,2,29,2,2,2,29,2,29,2,2,2,29,2,2,2,2,2,2,2,1
1,2,2,2,2,2,2,2,29,2,2,2,29,2,29,2,2,2,29,2,29,2,2,2,29,2,29,2,2,2,29,2,2,2,2,2,2,2,1
1,1,1,1,1,1,2,2,2,2,2,2,2,2,2,2,2,2,2,2,2,2,2,2,2,2,2,2,2,2,2,2,1,1,1,1,1,1,1
endlayer

layer
1,1,1,1,1,1,2,2,2,2,2,2,2,2,2,2,2,2,2,2,2,2,2,2,2,2,2,2,2,2,2,2,1,1,1,1,1,1,1
1,1,1,1,1,1,2,37,0,0,0,0,0,37,0,0,0,0,0,37,0,0,0,0,0,37,0,0,0,0,0,37,2,1,1,1,1,1,1
1,1,1,1,1,2,0,0,0,0,0,0,0,0,0,0,0,0,0,0,0,0,0,0,0,0,0,0,0,0,0,0,0,2,1,1,1,1,1
1,1,1,1,2,0,0,0,0,0,0,0,0,0,0,0,0,0,0,0,0,0,0,0,0,0,0,0,0,0,0,0,0,0,2,1,1,1,1
1,1,1,2,0,0,0,0,0,0,0,0,0,0,0,0,0,0,0,0,0,0,0,0,0,0,0,0,0,0,0,0,0,0,0,2,1,1,1
1,2,2,0,0,0,0,0,0,0,0,0,0,0,0,0,0,0,0,0,0,0,0,0,0,0,0,0,0,0,0,0,0,0,0,0,2,2,1
2,37,0,0,0,0,0,0,0,0,0,0,0,0,0,0,0,0,0,0,0,0,0,0,0,0,0,0,0,0,0,0,0,0,0,0,0,37,2
2,0,0,0,0,0,0,0,0,0,0,0,0,0,0,0,0,0,0,0,0,0,0,0,0,0,0,0,0,0,0,0,0,0,0,0,0,0,2
2,0,0,0,0,0,0,0,0,0,0,0,0,0,0,0,0,0,0,0,0,0,0,0,0,0,0,0,0,0,0,0,0,0,0,0,0,0,2
2,0,0,0,0,0,0,0,0,0,0,0,0,0,0,0,0,0,0,0,0,0,0,0,0,0,0,0,0,0,0,0,0,0,0,0,0,0,2
2,0,0,0,0,0,0,0,0,0,0,0,0,0,0,0,0,0,0,0,0,0,0,0,0,0,0,0,0,0,0,0,0,0,0,0,0,0,2
2,37,0,0,0,0,0,0,0,0,0,0,0,0,0,0,0,0,0,0,0,0,0,0,0,0,0,0,0,0,0,0,0,0,0,0,0,37,2
2,0,0,0,0,0,0,0,0,0,0,0,0,0,0,0,0,0,0,0,0,0,0,0,0,0,0,0,0,0,0,0,0,0,0,0,0,0,2
2,0,0,0,0,0,0,0,0,0,0,0,0,0,0,0,0,0,0,0,0,0,0,0,0,0,0,0,0,0,0,0,0,0,0,0,0,0,2
8,0,0,0,0,0,0,0,0,0,0,0,0,0,0,0,0,0,0,0,0,0,0,0,0,0,0,0,0,0,0,0,0,0,0,0,0,0,10
2,0,0,0,0,0,0,0,0,0,0,0,0,0,0,0,0,0,0,0,0,0,0,0,0,0,0,0,0,0,0,0,0,0,0,0,0,0,2
2,0,0,0,0,0,0,0,0,0,0,0,0,0,0,0,0,0,0,0,0,0,0,0,0,0,0,0,0,0,0,0,0,0,0,0,0,0,2
2,37,0,0,0,0,0,0,0,0,0,0,0,0,0,0,0,0,0,0,0,0,0,0,0,0,0,0,0,0,0,0,0,0,0,0,0,37,2
2,0,0,0,0,0,0,0,0,0,0,0,0,0,0,0,0,0,0,0,0,0,0,0,0,0,0,0,0,0,0,0,0,0,0,0,0,0,2
2,0,0,0,0,0,0,0,0,28,28,0,0,0,0,0,0,0,0,0,0,0,0,0,0,0,0,0,0,0,0,0,0,0,0,0,11,10,2
2,0,0,0,0,0,0,0,37,21,38,37,0,0,0,0,0,0,0,0,0,0,0,0,0,0,0,0,0,0,0,0,0,0,0,0,0,0,2
2,0,0,0,0,0,0,0,37,0,0,37,0,0,0,0,0,0,0,0,0,0,0,0,0,0,0,0,0,0,0,0,0,0,0,0,11,10,2
2,37,0,0,0,0,0,0,0,0,0,0,0,0,0,0,0,0,0,0,0,0,0,0,0,0,0,0,0,0,0,0,0,0,0,0,0,37,2
1,2,2,0,0,0,0,0,0,0,0,0,0,0,0,0,0,0,0,0,0,0,0,0,0,0,0,0,0,0,0,0,0,0,0,0,2,2,1
1,1,3,28,0,28,0,0,0,0,0,0,0,0,0,0,0,0,0,0,0,0,0,0,0,0,0,0,0,0,0,0,0,0,0,2,1,1,1
1,1,3,28,0,28,0,0,0,0,0,0,0,0,0,0,0,0,0,0,0,0,0,0,0,0,0,0,0,0,0,0,0,0,2,1,1,1,1
1,1,3,28,28,28,0,0,0,9,0,9,0,0,0,9,0,9,0,0,0,11,0,11,0,0,0,11,0,11,0,0,0,2,1,1,1,1,1
1,1,37,3,3,3,2,37,0,12,0,12,0,37,0,8,0,12,0,37,0,8,0,10,0,37,0,10,0,10,0,37,2,1,1,1,1,1,1
1,1,1,1,1,1,2,2,2,2,2,2,2,2,2,2,2,2,2,2,2,2,2,2,2,2,2,2,2,2,2,2,1,1,1,1,1,1,1
endlayer

layer
1,1,1,1,1,1,2,2,2,2,2,2,2,2,2,2,2,2,2,2,2,2,2,2,2,2,2,2,2,2,2,2,1,1,1,1,1,1,1
1,1,1,1,1,1,2,37,0,0,0,0,0,37,0,0,0,0,0,37,0,0,0,0,0,37,0,0,0,0,0,37,2,1,1,1,1,1,1
1,1,1,1,1,2,0,0,0,0,0,0,0,0,0,0,0,0,0,0,0,0,0,0,0,0,0,0,0,0,0,0,0,2,1,1,1,1,1
1,1,1,1,2,0,0,0,0,0,0,0,0,0,0,0,0,0,0,0,0,0,0,0,0,0,0,0,0,0,0,0,0,0,2,1,1,1,1
1,1,1,2,0,0,0,0,0,0,0,0,0,0,0,0,0,0,0,0,0,0,0,0,0,0,0,0,0,0,0,0,0,0,0,2,1,1,1
1,2,2,0,0,0,0,0,0,0,0,0,0,0,0,0,0,0,0,0,0,0,0,0,0,0,0,0,0,0,0,0,0,0,0,0,2,2,1
2,37,0,0,0,0,0,0,0,0,0,0,0,0,0,0,0,0,0,0,0,0,0,0,0,0,0,0,0,0,0,0,0,0,0,0,0,37,2
2,0,0,0,0,0,0,0,0,0,0,0,0,0,0,0,0,0,0,0,0,0,0,0,0,0,0,0,0,0,0,0,0,0,0,0,0,0,2
2,0,0,0,0,0,0,0,0,0,0,0,0,0,0,0,0,0,0,0,0,0,0,0,0,0,0,0,0,0,0,0,0,0,0,0,0,0,2
2,0,0,0,0,0,0,0,0,0,0,0,0,0,0,0,0,0,0,0,0,0,0,0,0,0,0,0,0,0,0,0,0,0,0,0,0,0,2
2,0,0,0,0,0,0,0,0,0,0,0,0,0,0,0,0,0,0,0,0,0,0,0,0,0,0,0,0,0,0,0,0,0,0,0,0,0,2
2,37,0,0,0,0,0,0,0,0,0,0,0,0,0,0,0,0,0,0,0,0,0,0,0,0,0,0,0,0,0,0,0,0,0,0,0,37,2
2,0,0,0,0,0,0,0,0,0,0,0,0,0,0,0,0,0,0,0,0,0,0,0,0,0,0,0,0,0,0,0,0,0,0,0,0,0,2
2,0,0,0,0,0,0,0,0,0,0,0,0,0,0,0,0,0,0,0,0,0,0,0,0,0,0,0,0,0,0,0,0,0,0,0,0,0,2
2,0,0,0,0,0,0,0,0,0,0,0,0,0,0,0,0,0,0,0,0,0,0,0,0,0,0,0,0,0,0,0,0,0,0,0,0,0,2
2,0,0,0,0,0,0,0,0,0,0,0,0,0,0,0,0,0,0,0,0,0,0,0,0,0,0,0,0,0,0,0,0,0,0,0,0,0,2
2,0,0,0,0,0,0,0,0,0,0,0,0,0,0,0,0,0,0,0,0,0,0,0,0,0,0,0,0,0,0,0,0,0,0,0,0,0,2
2,37,0,0,0,0,0,0,0,0,0,0,0,0,0,0,0,0,0,0,0,0,0,0,0,0,0,0,0,0,0,0,0,0,0,0,0,37,2
2,0,0,0,0,0,0,0,0,0,0,0,0,0,0,0,0,0,0,0,0,0,0,0,0,0,0,0,0,0,0,0,0,0,0,0,0,0,2
2,0,0,0,0,0,0,0,0,28,28,0,0,0,0,0,0,0,0,0,0,0,0,0,0,0,0,0,0,0,0,0,0,0,0,0,19,20,2
2,0,0,0,0,0,0,0,37,21,38,37,0,0,0,0,0,0,0,0,0,0,0,0,0,0,0,0,0,0,0,0,0,0,0,0,0,0,2
2,0,0,0,0,0,0,0,37,0,0,37,0,0,0,0,0,0,0,0,0,0,0,0,0,0,0,0,0,0,0,0,0,0,0,0,19,20,2
2,37,0,0,0,0,0,0,0,0,0,0,0,0,0,0,0,0,0,0,0,0,0,0,0,0,0,0,0,0,0,0,0,0,0,0,0,37,2
1,2,2,0,0,0,0,0,0,0,0,0,0,0,0,0,0,0,0,0,0,0,0,0,0,0,0,0,0,0,0,0,0,0,0,0,2,2,1
1,1,3,28,0,28,0,0,0,0,0,0,0,0,0,0,0,0,0,0,0,0,0,0,0,0,0,0,0,0,0,0,0,0,0,2,1,1,1
1,1,3,28,0,28,0,0,0,0,0,0,0,0,0,0,0,0,0,0,0,0,0,0,0,0,0,0,0,0,0,0,0,0,2,1,1,1,1
1,1,3,28,28,28,0,0,0,18,0,18,0,0,0,16,0,18,0,0,0,15,0,17,0,0,0,19,0,19,0,0,0,2,1,1,1,1,1
1,1,37,3,3,3,2,37,0,14,0,14,0,37,0,14,0,14,0,37,0,14,0,14,0,37,0,20,0,20,0,37,2,1,1,1,1,1,1
1,1,1,1,1,1,2,2,2,2,2,2,2,2,2,2,2,2,2,2,2,2,2,2,2,2,2,2,2,2,2,2,1,1,1,1,1,1,1
endlayer

layer
1,1,1,1,1,1,44,44,44,44,44,44,44,44,44,44,44,44,44,44,44,44,44,44,44,44,44,44,44,44,44,44,1,1,1,1,1,1,1
1,1,1,1,1,1,44,37,0,0,0,0,0,37,0,0,0,0,0,37,0,0,0,0,0,37,0,0,0,0,0,37,44,1,1,1,1,1,1
1,1,1,1,1,44,0,0,0,0,0,0,0,0,0,0,0,0,0,0,0,0,0,0,0,0,0,0,0,0,0,0,0,44,1,1,1,1,1
1,1,1,1,44,0,0,0,0,0,0,0,0,0,0,0,0,0,0,0,0,0,0,0,0,0,0,0,0,0,0,0,0,0,44,1,1,1,1
1,1,1,44,0,0,0,0,0,0,0,0,0,0,0,0,0,0,0,0,0,0,0,0,0,0,0,0,0,0,0,0,0,0,0,44,1,1,1
1,44,44,0,0,0,0,0,0,0,0,0,0,0,0,0,0,0,0,0,0,0,0,0,0,0,0,0,0,0,0,0,0,0,0,0,44,44,1
44,37,0,0,0,0,0,0,0,0,0,0,0,0,0,0,0,0,0,0,0,0,0,0,0,0,0,0,0,0,0,0,0,0,0,0,0,37,44
44,0,0,0,0,0,0,0,0,0,0,0,0,0,0,0,0,0,0,0,0,0,0,0,0,0,0,0,0,0,0,0,0,0,0,0,0,0,44
44,0,0,0,0,0,0,0,0,0,0,0,0,0,0,0,0,0,0,0,0,0,0,0,0,0,0,0,0,0,0,0,0,0,0,0,0,0,44
44,0,0,0,0,0,0,0,0,0,0,0,0,0,0,0,0,0,0,0,0,0,0,0,0,0,0,0,0,0,0,0,0,0,0,0,0,0,44
44,0,0,0,0,0,0,0,0,0,0,0,0,0,0,0,0,0,0,0,0,0,0,0,0,0,0,0,0,0,0,0,0,0,0,0,0,0,44
44,37,0,0,0,0,0,0,0,0,0,0,0,0,0,0,0,0,0,0,0,0,0,0,0,0,0,0,0,0,0,0,0,0,0,0,0,37,44
44,0,0,0,0,0,0,0,0,0,0,0,0,0,0,0,0,0,0,0,0,0,0,0,0,0,0,0,0,0,0,0,0,0,0,0,0,0,44
44,0,0,0,0,0,0,0,0,0,0,0,0,0,0,0,0,0,0,0,0,0,0,0,0,0,0,0,0,0,0,0,0,0,0,0,0,0,44
44,0,0,0,0,0,0,0,0,0,0,0,0,0,0,0,0,0,0,0,0,0,0,0,0,0,0,0,0,0,0,0,0,0,0,0,0,0,44
44,0,0,0,0,0,0,0,0,0,0,0,0,0,0,0,0,0,0,0,0,0,0,0,0,0,0,0,0,0,0,0,0,0,0,0,0,0,44
44,0,0,0,0,0,0,0,0,0,0,0,0,0,0,0,0,0,0,0,0,0,0,0,0,0,0,0,0,0,0,0,0,0,0,0,0,0,44
44,37,0,0,0,0,0,0,0,0,0,0,0,0,0,0,0,0,0,0,0,0,0,0,0,0,0,0,0,0,0,0,0,0,0,0,0,37,44
44,0,0,0,0,0,0,0,0,0,0,0,0,0,0,0,0,0,0,0,0,0,0,0,0,0,0,0,0,0,0,0,0,0,0,0,0,0,44
44,0,0,0,0,0,0,0,0,28,28,0,0,0,0,0,0,0,0,0,0,0,0,0,0,0,0,0,0,0,0,0,0,0,0,0,24,25,44
44,0,0,0,0,0,0,0,37,21,38,37,0,0,0,0,0,0,0,0,0,0,0,0,0,0,0,0,0,0,0,0,0,0,0,0,0,0,44
44,0,0,0,0,0,0,0,37,0,0,37,0,0,0,0,0,0,0,0,0,0,0,0,0,0,0,0,0,0,0,0,0,0,0,0,24,25,44
44,37,0,0,0,0,0,0,0,0,0,0,0,0,0,0,0,0,0,0,0,0,0,0,0,0,0,0,0,0,0,0,0,0,0,0,0,37,44
1,44,44,0,0,0,0,0,0,0,0,0,0,0,0,0,0,0,0,0,0,0,0,0,0,0,0,0,0,0,0,0,0,0,0,0,44,44,1
1,1,3,28,0,28,0,0,0,0,0,0,0,0,0,0,0,0,0,0,0,0,0,0,0,0,0,0,0,0,0,0,0,0,0,44,1,1,1
1,1,3,28,0,28,0,0,0,0,0,0,0,0,0,0,0,0,0,0,0,0,0,0,0,0,0,0,0,0,0,0,0,0,44,1,1,1,1
1,1,3,28,28,28,0,0,0,22,0,22,0,0,0,22,0,22,0,0,0,22,0,22,0,0,0,24,0,24,0,0,0,44,1,1,1,1,1
1,1,37,3,3,3,44,37,0,22,0,22,0,37,0,22,0,22,0,37,0,22,0,22,0,37,0,25,0,25,0,37,44,1,1,1,1,1,1
1,1,1,1,1,1,44,44,44,44,44,44,44,44,44,44,44,44,44,44,44,44,44,44,44,44,44,44,44,44,44,44,1,1,1,1,1,1,1
endlayer

layer
1,1,1,1,1,1,2,2,2,2,2,2,2,2,2,2,2,2,2,2,2,2,2,2,2,2,2,2,2,2,2,2,1,1,1,1,1,1,1
1,1,1,1,1,1,2,37,0,0,0,0,0,37,0,0,0,0,0,37,0,0,0,0,0,37,0,0,0,0,0,37,2,1,1,1,1,1,1
1,1,1,1,1,2,0,0,0,0,0,0,0,0,0,0,0,0,0,0,0,0,0,0,0,0,0,0,0,0,0,0,0,2,1,1,1,1,1
1,1,1,1,2,0,0,0,0,0,0,0,0,0,0,0,0,0,0,0,0,0,0,0,0,0,0,0,0,0,0,0,0,0,2,1,1,1,1
1,1,1,2,0,0,0,0,0,0,0,0,0,0,0,0,0,0,0,0,0,0,0,0,0,0,0,0,0,0,0,0,0,0,0,2,1,1,1
1,2,2,0,0,0,0,0,0,0,0,0,0,0,0,0,0,0,0,0,0,0,0,0,0,0,0,0,0,0,0,0,0,0,0,0,2,2,1
2,37,0,0,0,0,0,0,0,0,0,0,0,0,0,0,0,0,0,0,0,0,0,0,0,0,0,0,0,0,0,0,0,0,0,0,0,37,2
2,0,0,0,0,0,0,0,0,0,0,0,0,0,0,0,0,0,0,0,0,0,0,0,0,0,0,0,0,0,0,0,0,0,0,0,0,0,2
2,0,0,0,0,0,0,0,0,0,0,0,0,0,0,0,0,0,0,0,0,0,0,0,0,0,0,0,0,0,0,0,0,0,0,0,0,0,2
2,0,0,0,0,0,0,0,0,0,0,0,0,0,0,0,0,0,0,0,0,0,0,0,0,0,0,0,0,0,0,0,0,0,0,0,0,0,2
2,0,0,0,0,0,0,0,0,0,0,0,0,0,0,0,0,0,0,0,0,0,0,0,0,0,0,0,0,0,0,0,0,0,0,0,0,0,2
2,37,0,0,0,0,0,0,0,0,0,0,0,0,0,0,0,0,0,0,0,0,0,0,0,0,0,0,0,0,0,0,0,0,0,0,0,37,2
2,0,0,0,0,0,0,0,0,0,0,0,0,0,0,0,0,0,0,0,0,0,0,0,0,0,0,0,0,0,0,0,0,0,0,0,0,0,2
2,0,0,0,0,0,0,0,0,0,0,0,0,0,0,0,0,0,0,0,0,0,0,0,0,0,0,0,0,0,0,0,0,0,0,0,0,0,2
2,0,0,0,0,0,0,0,0,0,0,0,0,0,0,0,0,0,0,0,0,0,0,0,0,0,0,0,0,0,0,0,0,0,0,0,0,0,2
2,0,0,0,0,0,0,0,0,0,0,0,0,0,0,0,0,0,0,0,0,0,0,0,0,0,0,0,0,0,0,0,0,0,0,0,0,0,2
2,0,0,0,0,0,0,0,0,0,0,0,0,0,0,0,0,0,0,0,0,0,0,0,0,0,0,0,0,0,0,0,0,0,0,0,0,0,2
2,37,0,0,0,0,0,0,0,0,0,0,0,0,0,0,0,0,0,0,0,0,0,0,0,0,0,0,0,0,0,0,0,0,0,0,0,37,2
2,0,0,0,0,0,0,0,0,0,0,0,0,0,0,0,0,0,0,0,0,0,0,0,0,0,0,0,0,0,0,0,0,0,0,0,0,0,2
2,0,0,0,0,0,0,0,0,28,28,0,0,0,0,0,0,0,0,0,0,0,0,0,0,0,0,0,0,0,0,0,0,0,0,0,0,0,2
2,0,0,0,0,0,0,0,37,21,38,37,0,0,0,0,0,0,0,0,0,0,0,0,0,0,0,0,0,0,0,0,0,0,0,0,0,0,2
2,0,0,0,0,0,0,0,37,0,0,37,0,0,0,0,0,0,0,0,0,0,0,0,0,0,0,0,0,0,0,0,0,0,0,0,0,0,2
2,37,0,0,0,0,0,0,0,0,0,0,0,0,0,0,0,0,0,0,0,0,0,0,0,0,0,0,0,0,0,0,0,0,0,0,0,37,2
1,2,2,0,0,0,0,0,0,0,0,0,0,0,0,0,0,0,0,0,0,0,0,0,0,0,0,0,0,0,0,0,0,0,0,0,2,2,1
1,1,3,28,28,28,0,0,0,0,0,0,0,0,0,0,0,0,0,0,0,0,0,0,0,0,0,0,0,0,0,0,0,0,0,2,1,1,1
1,1,3,28,45,28,0,0,0,0,0,0,0,0,0,0,0,0,0,0,0,0,0,0,0,0,0,0,0,0,0,0,0,0,2,1,1,1,1
1,1,3,28,28,28,0,0,0,0,0,0,0,0,0,0,0,0,0,0,0,0,0,0,0,0,0,0,0,0,0,0,0,2,1,1,1,1,1
1,1,37,3,3,3,2,37,0,0,0,0,0,37,0,0,0,0,0,37,0,0,0,0,0,37,0,0,0,0,0,37,2,1,1,1,1,1,1
1,1,1,1,1,1,2,2,2,2,2,2,2,2,2,2,2,2,2,2,2,2,2,2,2,2,2,2,2,2,2,2,1,1,1,1,1,1,1
endlayer

layer
1,1,1,1,1,1,2,2,2,2,2,2,2,2,2,2,2,2,2,2,2,2,2,2,2,2,2,2,2,2,2,2,1,1,1,1,1,1,1
1,1,1,1,1,1,2,37,37,37,37,37,37,37,37,37,37,37,37,37,37,37,37,37,37,37,37,37,37,37,37,37,2,1,1,1,1,1,1
1,1,1,1,1,2,0,0,0,0,0,0,0,0,0,0,0,0,0,0,0,0,0,0,0,0,0,0,0,0,0,0,0,2,1,1,1,1,1
1,1,1,1,2,0,0,0,0,0,0,0,0,0,0,0,0,0,0,0,0,0,0,0,0,0,0,0,0,0,0,0,0,0,2,1,1,1,1
1,1,1,2,0,0,0,0,0,0,0,0,0,0,0,0,0,0,0,0,0,0,0,0,0,0,0,0,0,0,0,0,0,0,0,2,1,1,1
1,2,2,0,0,0,0,0,0,0,0,0,0,0,0,0,0,0,0,0,0,0,0,0,0,0,0,0,0,0,0,0,0,0,0,0,2,2,1
2,37,0,0,0,0,0,0,0,0,0,0,0,0,0,0,0,0,0,0,0,0,0,0,0,0,0,0,0,0,0,0,0,0,0,0,0,37,2
2,37,0,0,0,0,0,0,0,0,0,0,0,0,0,0,0,0,0,0,0,0,0,0,0,0,0,0,0,0,0,0,0,0,0,0,0,37,2
2,37,0,0,0,0,0,0,0,0,0,0,0,0,0,0,0,0,0,0,0,0,0,0,0,0,0,0,0,0,0,0,0,0,0,0,0,37,2
2,37,0,0,0,0,0,0,0,0,0,0,0,0,0,0,0,0,0,0,0,0,0,0,0,0,0,0,0,0,0,0,0,0,0,0,0,37,2
2,37,0,0,0,0,0,0,0,0,0,0,0,0,0,0,0,0,0,0,0,0,0,0,0,0,0,0,0,0,0,0,0,0,0,0,0,37,2
2,37,0,0,0,0,0,0,0,0,0,0,0,0,0,0,0,0,0,0,0,0,0,0,0,0,0,0,0,0,0,0,0,0,0,0,0,37,2
2,37,0,0,0,0,0,0,0,0,0,0,0,0,0,0,0,0,0,0,0,0,0,0,0,0,0,0,0,0,0,0,0,0,0,0,0,37,2
2,37,0,0,0,0,0,0,0,0,0,0,0,0,0,0,0,0,0,0,0,0,0,0,0,0,0,0,0,0,0,0,0,0,0,0,0,37,2
2,37,0,0,0,0,0,0,0,0,0,0,0,0,0,0,0,0,0,0,0,0,0,0,0,0,0,0,0,0,0,0,0,0,0,0,0,37,2
2,37,0,0,0,0,0,0,0,0,0,0,0,0,0,0,0,0,0,0,0,0,0,0,0,0,0,0,0,0,0,0,0,0,0,0,0,37,2
2,37,0,0,0,0,0,0,0,0,0,0,0,0,0,0,0,0,0,0,0,0,0,0,0,0,0,0,0,0,0,0,0,0,0,0,0,37,2
2,37,0,0,0,0,0,0,0,0,0,0,0,0,0,0,0,0,0,0,0,0,0,0,0,0,0,0,0,0,0,0,0,0,0,0,0,37,2
2,37,0,0,0,0,0,0,0,0,0,0,0,0,0,0,0,0,0,0,0,0,0,0,0,0,0,0,0,0,0,0,0,0,0,0,0,37,2
2,37,0,0,0,0,0,0,0,28,28,0,0,0,0,0,0,0,0,0,0,0,0,0,0,0,0,0,0,0,0,0,0,0,0,0,0,37,2
2,37,0,0,0,0,0,0,37,21,38,37,0,0,0,0,0,0,0,0,0,0,0,0,0,0,0,0,0,0,0,0,0,0,0,0,0,37,2
2,37,0,0,0,0,0,0,37,0,0,37,0,0,0,0,0,0,0,0,0,0,0,0,0,0,0,0,0,0,0,0,0,0,0,0,0,37,2
2,37,0,0,0,0,0,0,0,0,0,0,0,0,0,0,0,0,0,0,0,0,0,0,0,0,0,0,0,0,0,0,0,0,0,0,0,37,2
1,2,2,42,42,42,40,0,0,0,0,0,0,0,0,0,0,0,0,0,0,0,0,0,0,0,0,0,0,0,0,0,0,0,0,0,2,2,1
1,1,3,28,28,28,40,0,0,0,0,0,0,0,0,0,0,0,0,0,0,0,0,0,0,0,0,0,0,0,0,0,0,0,0,2,1,1,1
1,1,3,28,0,28,40,0,0,0,0,0,0,0,0,0,0,0,0,0,0,0,0,0,0,0,0,0,0,0,0,0,0,0,2,1,1,1,1
1,1,3,28,28,28,40,0,0,0,0,0,0,0,0,0,0,0,0,0,0,0,0,0,0,0,0,0,0,0,0,0,0,2,1,1,1,1,1
1,1,37,3,3,3,2,37,37,37,37,37,37,37,37,37,37,37,37,37,37,37,37,37,37,37,37,37,37,37,37,37,2,1,1,1,1,1,1
1,1,1,1,1,1,2,2,2,2,2,2,2,2,2,2,2,2,2,2,2,2,2,2,2,2,2,2,2,2,2,2,1,1,1,1,1,1,1
endlayer

layer
1,1,1,1,1,1,1,1,1,1,1,1,1,1,1,1,1,1,1,1,1,1,1,1,1,1,1,1,1,1,1,1,1,1,1,1,1,1,1
1,1,1,1,1,1,2,2,4,2,2,2,2,4,2,2,2,2,2,4,2,2,2,2,4,2,2,2,2,4,2,2,2,1,1,1,1,1,1
1,1,1,1,1,2,46,46,5,46,46,46,46,5,46,46,46,46,46,5,46,46,46,46,5,46,46,46,46,5,46,46,46,2,1,1,1,1,1
1,1,1,1,4,46,46,46,46,46,46,46,46,46,46,46,46,46,46,46,46,46,46,46,46,46,46,46,46,46,46,46,46,46,4,1,1,1,1
1,1,1,2,5,46,46,46,46,46,46,46,46,46,46,46,46,46,46,46,46,46,46,46,46,46,46,46,46,46,46,46,46,46,5,2,1,1,1
1,1,2,46,46,46,46,46,46,46,46,46,46,46,46,46,46,46,46,46,46,46,46,46,46,46,46,46,46,46,46,46,46,46,46,46,2,1,1
1,2,46,46,46,46,46,46,46,46,46,46,46,46,46,46,46,46,46,46,46,46,46,46,46,46,46,46,46,46,46,46,46,46,46,46,46,2,1
1,2,46,46,46,46,46,46,46,37,37,37,37,37,37,37,37,37,37,37,37,37,37,37,37,37,37,37,37,37,46,46,46,46,46,46,46,2,1
1,2,46,46,46,46,46,46,37,37,0,0,0,0,0,0,0,0,0,0,0,0,0,0,0,0,0,0,0,37,37,46,46,46,46,46,46,2,1
1,4,5,46,46,46,46,37,37,0,0,0,0,0,0,0,0,0,0,0,0,0,0,0,0,0,0,0,0,0,37,37,46,46,46,46,5,4,1
1,2,46,46,46,46,46,37,0,0,0,0,0,0,0,0,0,0,0,0,0,0,0,0,0,0,0,0,0,0,0,37,46,46,46,46,46,2,1
1,2,46,46,46,46,46,37,0,0,0,0,0,0,0,0,0,0,0,0,0,0,0,0,0,0,0,0,0,0,0,37,46,46,46,46,46,2,1
1,2,46,46,46,46,46,37,0,0,0,0,0,0,0,0,0,0,0,0,0,0,0,0,0,0,0,0,0,0,0,37,46,46,46,46,46,2,1
1,2,46,46,46,46,46,37,0,0,0,0,0,0,0,0,0,0,0,0,0,0,0,0,0,0,0,0,0,0,0,37,46,46,46,46,46,2,1
1,4,5,46,46,46,46,37,0,0,0,0,0,0,0,0,0,0,0,0,0,0,0,0,0,0,0,0,0,0,0,37,46,46,46,46,5,4,1
1,2,46,46,46,46,46,37,0,0,0,0,0,0,0,0,0,0,0,0,0,0,0,0,0,0,0,0,0,0,0,37,46,46,46,46,46,2,1
1,2,46,46,46,46,46,37,0,0,0,0,0,0,0,0,0,0,0,0,0,0,0,0,0,0,0,0,0,0,0,37,46,46,46,46,46,2,1
1,2,46,46,46,46,46,37,0,0,0,0,0,0,0,0,0,0,0,0,0,0,0,0,0,0,0,0,0,0,0,37,46,46,46,46,46,2,1
1,2,46,46,46,46,46,37,0,0,0,0,0,0,0,0,0,0,0,0,0,0,0,0,0,0,0,0,0,0,0,37,46,46,46,46,46,2,1
1,4,5,46,46,46,46,37,0,28,28,0,0,0,0,0,0,0,0,0,0,0,0,0,0,0,0,0,0,0,37,37,46,46,46,46,5,4,1
1,2,46,46,46,46,46,37,37,21,38,37,0,0,0,0,0,0,0,0,0,0,0,0,0,0,0,0,0,37,37,46,46,46,46,46,46,2,1
1,2,46,46,46,46,46,37,37,37,37,37,37,37,37,37,37,37,37,37,37,37,37,37,37,37,37,37,37,37,46,46,46,46,46,46,46,2,1
1,2,46,46,46,46,46,46,46,46,46,46,46,46,46,46,46,46,46,46,46,46,46,46,46,46,46,46,46,46,46,46,46,46,46,46,46,2,1
1,1,37,3,3,3,37,46,46,46,46,46,46,46,46,46,46,46,46,46,46,46,46,46,46,46,46,46,46,46,46,46,46,46,46,46,2,1,1
1,1,3,28,28,28,3,46,46,46,46,46,46,46,46,46,46,46,46,46,46,46,46,46,46,46,46,46,46,46,46,46,46,46,5,2,1,1,1
1,1,3,28,0,28,3,46,46,46,46,46,46,46,46,46,46,46,46,46,46,46,46,46,46,46,46,46,46,46,46,46,46,46,4,1,1,1,1
1,1,3,28,28,28,3,46,5,46,46,46,46,5,46,46,46,46,46,5,46,46,46,46,5,46,46,46,46,5,46,46,46,2,1,1,1,1,1
1,1,37,3,3,3,37,2,4,2,2,2,2,4,2,2,2,2,2,4,2,2,2,2,4,2,2,2,2,4,2,2,2,1,1,1,1,1,1
1,1,1,1,1,1,1,1,1,1,1,1,1,1,1,1,1,1,1,1,1,1,1,1,1,1,1,1,1,1,1,1,1,1,1,1,1,1,1
endlayer

layer
1,1,1,1,1,1,1,1,1,1,1,1,1,1,1,1,1,1,1,1,1,1,1,1,1,1,1,1,1,1,1,1,1,1,1,1,1,1,1
1,1,1,1,1,1,1,1,1,1,1,1,1,1,1,1,1,1,1,1,1,1,1,1,1,1,1,1,1,1,1,1,1,1,1,1,1,1,1
1,1,1,1,1,1,1,1,1,1,1,1,1,1,1,1,1,1,1,1,1,1,1,1,1,1,1,1,1,1,1,1,1,1,1,1,1,1,1
1,1,1,1,1,1,1,1,1,1,1,1,1,1,1,1,1,1,1,1,1,1,1,1,1,1,1,1,1,1,1,1,1,1,1,1,1,1,1
1,1,1,1,1,1,1,1,1,1,1,1,1,1,1,1,1,1,1,1,1,1,1,1,1,1,1,1,1,1,1,1,1,1,1,1,1,1,1
1,1,1,1,1,1,1,1,1,1,1,1,1,1,1,1,1,1,1,1,1,1,1,1,1,1,1,1,1,1,1,1,1,1,1,1,1,1,1
1,1,1,1,1,1,1,1,1,1,1,1,1,1,1,1,1,1,1,1,1,1,1,1,1,1,1,1,1,1,1,1,1,1,1,1,1,1,1
1,1,1,1,1,1,1,1,1,2,2,2,2,2,2,2,2,2,2,2,2,2,2,2,2,2,2,2,2,2,1,1,1,1,1,1,1,1,1
1,1,1,1,1,1,1,1,2,2,37,37,37,37,37,37,37,37,37,37,37,37,37,37,37,37,37,37,37,2,2,1,1,1,1,1,1,1,1
1,1,1,1,1,1,1,2,2,37,0,0,37,0,0,0,0,37,0,0,0,37,0,0,0,0,37,0,0,37,2,2,1,1,1,1,1,1,1
1,1,1,1,1,1,1,2,37,0,0,0,37,0,0,0,0,37,0,0,0,37,0,0,0,0,37,0,0,0,37,2,1,1,1,1,1,1,1
1,1,1,1,1,1,1,2,37,37,37,37,37,37,37,37,37,37,37,37,37,37,37,37,37,37,37,37,37,37,37,2,1,1,1,1,1,1,1
1,1,1,1,1,1,1,2,37,0,0,0,37,0,0,0,0,37,0,0,0,37,0,0,0,0,37,0,0,0,37,2,1,1,1,1,1,1,1
1,1,1,1,1,1,1,2,37,0,0,0,37,0,0,0,0,37,0,0,0,37,0,0,0,0,37,0,0,0,37,2,1,1,1,1,1,1,1
1,1,1,1,1,1,1,2,37,37,37,37,37,37,37,37,37,37,37,37,37,37,37,37,37,37,37,37,37,37,37,2,1,1,1,1,1,1,1
1,1,1,1,1,1,1,2,37,0,0,0,37,0,0,0,0,37,0,0,0,37,0,0,0,0,37,0,0,0,37,2,1,1,1,1,1,1,1
1,1,1,1,1,1,1,2,37,0,0,0,37,0,0,0,0,37,0,0,0,37,0,0,0,0,37,0,0,0,37,2,1,1,1,1,1,1,1
1,1,1,1,1,1,1,37,37,37,37,37,37,37,37,37,37,37,37,37,37,37,37,37,37,37,37,37,37,37,37,2,1,1,1,1,1,1,1
1,1,1,1,1,1,1,37,0,0,0,0,37,0,0,0,0,37,0,0,0,37,0,0,0,0,37,0,0,0,37,2,1,1,1,1,1,1,1
1,1,1,1,1,1,1,37,0,28,28,0,37,0,0,0,0,37,0,0,0,37,0,0,0,0,37,0,0,37,2,2,1,1,1,1,1,1,1
1,1,1,1,1,1,1,37,37,21,38,37,37,37,37,37,37,37,37,37,37,37,37,37,37,37,37,37,37,2,2,1,1,1,1,1,1,1,1
1,1,1,1,1,1,1,37,37,37,37,37,37,2,2,2,2,2,2,2,2,2,2,2,2,2,2,2,2,2,1,1,1,1,1,1,1,1,1
1,1,1,1,1,1,1,1,1,1,1,1,1,1,1,1,1,1,1,1,1,1,1,1,1,1,1,1,1,1,1,1,1,1,1,1,1,1,1
1,1,37,3,3,3,37,1,1,1,1,1,1,1,1,1,1,1,1,1,1,1,1,1,1,1,1,1,1,1,1,1,1,1,1,1,1,1,1
1,1,3,28,28,28,3,1,1,1,1,1,1,1,1,1,1,1,1,1,1,1,1,1,1,1,1,1,1,1,1,1,1,1,1,1,1,1,1
1,1,3,28,45,28,3,1,1,1,1,1,1,1,1,1,1,1,1,1,1,1,1,1,1,1,1,1,1,1,1,1,1,1,1,1,1,1,1
1,1,3,28,28,28,3,1,1,1,1,1,1,1,1,1,1,1,1,1,1,1,1,1,1,1,1,1,1,1,1,1,1,1,1,1,1,1,1
1,1,37,3,3,3,37,37,1,1,1,1,1,1,1,1,1,1,1,1,1,1,1,1,1,1,1,1,1,1,1,1,1,1,1,1,1,1,1
1,1,1,1,1,1,1,1,1,1,1,1,1,1,1,1,1,1,1,1,1,1,1,1,1,1,1,1,1,1,1,1,1,1,1,1,1,1,1
endlayer

layer
1,1,1,1,1,1,1,1,1,1,1,1,1,1,1,1,1,1,1,1,1,1,1,1,1,1,1,1,1,1,1,1,1,1,1,1,1,1,1
1,1,1,1,1,1,1,1,1,1,1,1,1,1,1,1,1,1,1,1,1,1,1,1,1,1,1,1,1,1,1,1,1,1,1,1,1,1,1
1,1,1,1,1,1,1,1,1,1,1,1,1,1,1,1,1,1,1,1,1,1,1,1,1,1,1,1,1,1,1,1,1,1,1,1,1,1,1
1,1,1,1,1,1,1,1,1,1,1,1,1,1,1,1,1,1,1,1,1,1,1,1,1,1,1,1,1,1,1,1,1,1,1,1,1,1,1
1,1,1,1,1,1,1,1,1,1,1,1,1,1,1,1,1,1,1,1,1,1,1,1,1,1,1,1,1,1,1,1,1,1,1,1,1,1,1
1,1,1,1,1,1,1,1,1,1,1,1,1,1,1,1,1,1,1,1,1,1,1,1,1,1,1,1,1,1,1,1,1,1,1,1,1,1,1
1,1,1,1,1,1,1,1,1,1,1,1,1,1,1,1,1,1,1,1,1,1,1,1,1,1,1,1,1,1,1,1,1,1,1,1,1,1,1
1,1,1,1,1,1,1,1,1,1,1,1,1,1,1,1,1,1,1,1,1,1,1,1,1,1,1,1,1,1,1,1,1,1,1,1,1,1,1
1,1,1,1,1,1,1,1,1,2,2,2,2,2,2,2,2,2,2,2,2,2,2,2,2,2,2,2,2,2,1,1,1,1,1,1,1,1,1
1,1,1,1,1,1,1,1,2,2,46,46,2,46,46,46,46,2,46,46,46,2,46,46,46,46,2,46,46,2,2,1,1,1,1,1,1,1,1
1,1,1,1,1,1,1,1,2,46,5,46,2,46,5,46,46,2,46,5,46,2,46,46,5,46,2,46,5,46,2,1,1,1,1,1,1,1,1
1,1,1,1,1,1,1,1,2,2,4,2,2,2,4,2,2,2,2,4,2,2,2,2,4,2,2,2,4,2,2,1,1,1,1,1,1,1,1
1,1,1,1,1,1,1,1,2,46,5,46,2,46,5,46,46,2,46,5,46,2,46,46,5,46,2,46,5,46,2,1,1,1,1,1,1,1,1
1,1,1,1,1,1,1,1,2,46,46,46,2,46,46,46,46,2,46,46,46,2,46,46,46,46,2,46,46,46,2,1,1,1,1,1,1,1,1
1,1,1,1,1,1,1,1,2,2,4,2,2,2,2,2,2,2,2,2,2,2,2,2,2,2,2,2,2,2,2,1,1,1,1,1,1,1,1
1,1,1,1,1,1,1,1,2,46,5,46,2,46,46,46,46,2,46,46,46,2,46,46,46,46,2,46,46,46,2,1,1,1,1,1,1,1,1
1,1,1,1,1,1,1,1,2,46,46,46,2,46,5,46,46,2,46,5,46,2,46,46,5,46,2,46,5,46,2,1,1,1,1,1,1,1,1
1,1,1,1,1,1,1,37,3,3,3,3,37,2,4,2,2,2,2,4,2,2,2,2,4,2,2,2,4,2,2,1,1,1,1,1,1,1,1
1,1,1,1,1,1,1,3,0,0,0,0,3,46,5,46,46,2,46,5,46,2,46,46,5,46,2,46,5,46,2,1,1,1,1,1,1,1,1
1,1,1,1,1,1,1,3,0,28,28,0,3,46,46,46,46,2,46,46,46,2,46,46,46,46,2,46,46,2,2,1,1,1,1,1,1,1,1
1,1,1,1,1,1,1,3,37,21,38,37,3,2,2,2,2,2,2,2,2,2,2,2,2,2,2,2,2,2,1,1,1,1,1,1,1,1,1
1,1,1,1,1,1,1,37,3,3,3,3,37,1,1,1,1,1,1,1,1,1,1,1,1,1,1,1,1,1,1,1,1,1,1,1,1,1,1
1,1,1,1,1,1,1,1,1,1,1,1,1,1,1,1,1,1,1,1,1,1,1,1,1,1,1,1,1,1,1,1,1,1,1,1,1,1,1
1,1,37,3,3,3,37,1,1,1,1,1,1,1,1,1,1,1,1,1,1,1,1,1,1,1,1,1,1,1,1,1,1,1,1,1,1,1,1
1,1,3,28,28,28,3,1,1,1,1,1,1,1,1,1,1,1,1,1,1,1,1,1,1,1,1,1,1,1,1,1,1,1,1,1,1,1,1
1,1,3,28,0,28,3,1,1,1,1,1,1,1,1,1,1,1,1,1,1,1,1,1,1,1,1,1,1,1,1,1,1,1,1,1,1,1,1
1,1,3,28,28,28,3,1,1,1,1,1,1,1,1,1,1,1,1,1,1,1,1,1,1,1,1,1,1,1,1,1,1,1,1,1,1,1,1
1,1,37,3,3,3,37,37,1,1,1,1,1,1,1,1,1,1,1,1,1,1,1,1,1,1,1,1,1,1,1,1,1,1,1,1,1,1,1
1,1,1,1,1,1,1,1,1,1,1,1,1,1,1,1,1,1,1,1,1,1,1,1,1,1,1,1,1,1,1,1,1,1,1,1,1,1,1
endlayer

