# Gilly's Wheat garden for bakery

weight=1
embed_into_distance=1
unacceptable_target_blocks=flowing_water,water,flowing_lava,lava
dimensions=5,9,9
max_leveling=2
leveling_buffer=0
preserve_water=0
preserve_lava=0
preserve_plants=0

rule1=0,100,dirt
rule2=0,100,stonebrick
rule3=0,100,farmland
rule4=0,100,flowing_water
rule5=0,100,wheat-2
rule6=0,100,fence
rule7=0,100,torch

layer
2,2,2,2,2,2,2,2,2
2,1,1,1,1,1,1,1,2
2,1,1,1,1,1,1,1,2
2,1,1,1,1,1,1,1,2
2,1,1,1,2,1,1,1,2
2,1,1,1,1,1,1,1,2
2,1,1,1,1,1,1,1,2
2,1,1,1,1,1,1,1,2
2,2,2,2,2,2,2,2,2
endlayer

layer
2,2,2,2,2,2,2,2,2
2,3,3,3,3,3,3,3,2
2,3,3,3,3,3,3,3,2
2,3,3,3,3,3,3,3,2
2,3,3,3,4,3,3,3,2
2,3,3,3,3,3,3,3,2
2,3,3,3,3,3,3,3,2
2,3,3,3,3,3,3,3,2
2,2,2,2,2,2,2,2,2
endlayer

layer
0,0,0,0,0,0,0,0,0
0,5,5,5,5,5,5,5,0
0,5,5,5,5,5,5,5,0
0,5,5,5,5,5,5,5,0
0,5,5,5,6,5,5,5,0
0,5,5,5,5,5,5,5,0
0,5,5,5,5,5,5,5,0
0,5,5,5,5,5,5,5,0
0,0,0,0,0,0,0,0,0
endlayer

layer
0,0,0,0,0,0,0,0,0
0,0,0,0,0,0,0,0,0
0,0,0,0,0,0,0,0,0
0,0,0,0,0,0,0,0,0
0,0,0,0,6,0,0,0,0
0,0,0,0,0,0,0,0,0
0,0,0,0,0,0,0,0,0
0,0,0,0,0,0,0,0,0
0,0,0,0,0,0,0,0,0
endlayer

layer
0,0,0,0,0,0,0,0,0
0,0,0,0,0,0,0,0,0
0,0,0,0,0,0,0,0,0
0,0,0,0,0,0,0,0,0
0,0,0,0,7,0,0,0,0
0,0,0,0,0,0,0,0,0
0,0,0,0,0,0,0,0,0
0,0,0,0,0,0,0,0,0
0,0,0,0,0,0,0,0,0
endlayer
