# Gilly's Fountain for Village Center

weight=1
embed_into_distance=1
unacceptable_target_blocks=flowing_water,water,flowing_lava,lava
dimensions=7,13,13
max_leveling=2
leveling_buffer=0
preserve_water=0
preserve_lava=0
preserve_plants=0

rule1=0,100,stonebrick
rule2=0,100,stone_slab
rule3=0,100,stone_slab-5
rule4=0,100,stone_brick_stairs
rule5=0,100,stone_brick_stairs-1
rule6=0,100,stone_brick_stairs-2
rule7=0,100,stone_brick_stairs-3
rule8=0,100,flowing_water


layer
4,4,4,1,1,1,1,1,1,1,4,4,6
7,1,7,1,1,1,1,1,1,1,6,1,6
7,4,1,1,1,1,1,1,1,1,1,4,6
1,1,1,1,1,1,1,1,1,1,1,1,1
1,1,1,1,1,1,1,1,1,1,1,1,1
1,1,1,1,1,1,1,1,1,1,1,1,1
1,1,1,1,1,1,1,1,1,1,1,1,1
1,1,1,1,1,1,1,1,1,1,1,1,1
1,1,1,1,1,1,1,1,1,1,1,1,1
1,1,1,1,1,1,1,1,1,1,1,1,1
7,5,1,1,1,1,1,1,1,1,1,5,6
7,1,7,1,1,1,1,1,1,1,6,1,6
7,5,5,1,1,1,1,1,1,1,5,5,5
endlayer


layer
0,0,0,4,1,6,4,7,1,4,0,0,0
0,0,0,7,8,8,8,8,8,6,0,0,0
0,0,3,1,8,8,8,8,8,1,3,0,0
7,4,1,1,1,8,1,8,1,1,1,4,6
1,8,8,1,1,1,1,1,1,1,8,8,1
5,8,8,8,1,1,1,1,1,8,8,8,5
7,8,8,1,1,1,1,1,1,1,8,8,6
4,8,8,8,1,1,1,1,1,8,8,8,4
1,8,8,1,1,1,1,1,1,1,8,8,1
7,5,1,1,1,8,1,8,1,1,1,5,6
0,0,3,1,8,8,8,8,8,1,3,0,0
0,0,0,7,8,8,8,8,8,6,0,0,0
0,0,0,5,1,6,5,7,1,5,0,0,0
endlayer

layer
0,0,0,0,2,0,0,0,2,0,0,0,0
0,0,0,0,0,0,0,0,0,0,0,0,0
0,0,0,3,0,0,0,0,0,3,0,0,0
0,0,3,1,4,0,1,0,4,1,3,0,0
2,0,0,7,8,8,8,8,8,6,0,0,2
0,0,0,0,8,8,8,8,8,0,0,0,0
0,0,0,1,8,8,2,8,8,1,0,0,0
0,0,0,0,8,8,8,8,8,0,0,0,0
2,0,0,7,8,8,8,8,8,6,0,0,2
0,0,3,1,5,0,1,0,5,1,3,0,0
0,0,0,3,0,0,0,0,0,3,0,0,0
0,0,0,0,0,0,0,0,0,0,0,0,0
0,0,0,0,2,0,0,0,2,0,0,0,0
endlayer

layer
0,0,0,0,0,0,0,0,0,0,0,0,0
0,0,0,0,0,0,0,0,0,0,0,0,0
0,0,0,0,0,0,0,0,0,0,0,0,0
0,0,0,0,0,0,2,0,0,0,0,0,0
0,0,0,0,0,0,0,0,0,0,0,0,0
0,0,0,0,0,0,0,0,0,0,0,0,0
0,0,0,2,0,0,2,0,0,2,0,0,0
0,0,0,0,0,0,0,0,0,0,0,0,0
0,0,0,0,0,0,0,0,0,0,0,0,0
0,0,0,0,0,0,2,0,0,0,0,0,0
0,0,0,0,0,0,0,0,0,0,0,0,0
0,0,0,0,0,0,0,0,0,0,0,0,0
0,0,0,0,0,0,0,0,0,0,0,0,0
endlayer

layer
0,0,0,0,0,0,0,0,0,0,0,0,0
0,0,0,0,0,0,0,0,0,0,0,0,0
0,0,0,0,0,0,0,0,0,0,0,0,0
0,0,0,0,0,0,0,0,0,0,0,0,0
0,0,0,0,0,0,0,0,0,0,0,0,0
0,0,0,0,0,0,0,0,0,0,0,0,0
0,0,0,0,0,0,2,0,0,0,0,0,0
0,0,0,0,0,0,0,0,0,0,0,0,0
0,0,0,0,0,0,0,0,0,0,0,0,0
0,0,0,0,0,0,0,0,0,0,0,0,0
0,0,0,0,0,0,0,0,0,0,0,0,0
0,0,0,0,0,0,0,0,0,0,0,0,0
0,0,0,0,0,0,0,0,0,0,0,0,0
endlayer

layer
0,0,0,0,0,0,0,0,0,0,0,0,0
0,0,0,0,0,0,0,0,0,0,0,0,0
0,0,0,0,0,0,0,0,0,0,0,0,0
0,0,0,0,0,0,0,0,0,0,0,0,0
0,0,0,0,0,0,0,0,0,0,0,0,0
0,0,0,0,0,0,0,0,0,0,0,0,0
0,0,0,0,0,0,2,0,0,0,0,0,0
0,0,0,0,0,0,0,0,0,0,0,0,0
0,0,0,0,0,0,0,0,0,0,0,0,0
0,0,0,0,0,0,0,0,0,0,0,0,0
0,0,0,0,0,0,0,0,0,0,0,0,0
0,0,0,0,0,0,0,0,0,0,0,0,0
0,0,0,0,0,0,0,0,0,0,0,0,0
endlayer

layer
0,0,0,0,0,0,0,0,0,0,0,0,0
0,0,0,0,0,0,0,0,0,0,0,0,0
0,0,0,0,0,0,0,0,0,0,0,0,0
0,0,0,0,0,0,0,0,0,0,0,0,0
0,0,0,0,0,0,0,0,0,0,0,0,0
0,0,0,0,0,0,0,0,0,0,0,0,0
0,0,0,0,0,0,8,0,0,0,0,0,0
0,0,0,0,0,0,0,0,0,0,0,0,0
0,0,0,0,0,0,0,0,0,0,0,0,0
0,0,0,0,0,0,0,0,0,0,0,0,0
0,0,0,0,0,0,0,0,0,0,0,0,0
0,0,0,0,0,0,0,0,0,0,0,0,0
0,0,0,0,0,0,0,0,0,0,0,0,0
endlayer