# Gilly's TowerPortal Atlantis-tech

weight=1
embed_into_distance=2
unacceptable_target_blocks=flowing_water,water,flowing_lava,lava
dimensions=39,13,13
max_leveling=2
leveling_buffer=0
preserve_water=0
preserve_lava=0
preserve_plants=0

rule1=0,100,stonebrick
rule2=0,100,stained_glass_pane-3
rule3=0,100,stone_slab-5
rule4=0,100,stone_brick_stairs
rule5=0,100,stone_brick_stairs-1
rule6=0,100,stone_brick_stairs-2
rule7=0,100,stone_brick_stairs-3
rule8=0,100,quartz_stairs-7
rule9=0,100,quartz_stairs-6
rule10=0,100,quartz_block
rule11=0,100,stone_slab-13
rule12=0,100,stone_slab-15
rule13=0,100,fence
rule14=0,100,torch-5
rule15=0,100,obsidian

layer
1,1,1,1,1,1,1,1,1,1,1,1,1
1,1,1,1,1,1,1,1,1,1,1,1,1
1,1,1,1,1,1,1,1,1,1,1,1,1
1,1,1,1,1,1,1,1,1,1,1,1,1
1,1,1,1,1,1,1,1,1,1,1,1,1
1,1,1,1,1,1,1,1,1,1,1,1,1
1,1,1,1,1,1,1,1,1,1,1,1,1
1,1,1,1,1,1,1,1,1,1,1,1,1
1,1,1,1,1,1,1,1,1,1,1,1,1
1,1,1,1,1,1,1,1,1,1,1,1,1
1,1,1,1,1,1,1,1,1,1,1,1,1
1,1,1,1,1,1,1,1,1,1,1,1,1
1,1,1,1,1,1,1,1,1,1,1,1,1
endlayer

layer
5,5,5,5,5,5,5,5,5,5,5,5,5
6,2,2,2,2,2,2,2,2,2,2,2,7
6,2,14,1,1,1,14,1,1,1,14,2,7
6,2,1,1,1,1,1,1,1,1,1,2,7
6,2,1,1,1,1,1,1,1,1,1,2,7
1,1,1,1,1,1,1,1,1,1,1,1,1
1,1,1,1,1,1,1,1,1,1,1,1,1
1,1,1,1,1,1,1,1,1,1,1,1,1
6,2,1,1,1,1,1,1,1,1,1,2,7
6,2,1,1,1,1,1,1,1,1,1,2,7
6,2,14,1,1,1,14,1,1,1,14,2,7
6,2,2,2,2,2,2,2,2,2,2,2,7
4,4,4,4,4,4,4,4,4,4,4,4,4
endlayer


layer
0,0,0,0,0,0,0,0,0,0,0,0,0
0,3,3,3,3,3,3,3,3,3,3,3,0
0,3,5,5,5,5,5,5,5,5,5,3,0
0,3,6,2,2,2,2,2,2,2,7,3,0
0,1,1,1,14,1,1,1,14,1,1,1,0
3,1,1,2,2,2,2,2,2,2,1,1,3
1,2,2,2,14,12,12,12,14,2,2,2,1
3,1,1,2,2,2,2,2,2,2,1,1,3
0,1,1,1,14,1,1,1,14,1,1,1,0
0,3,6,2,2,2,2,2,2,2,7,3,0
0,3,4,4,4,4,4,4,4,4,4,3,0
0,3,3,3,3,3,3,3,3,3,3,3,0
0,0,0,0,0,0,0,0,0,0,0,0,0
endlayer

layer
0,0,0,0,0,0,0,0,0,0,0,0,0
0,0,0,0,0,0,0,0,0,0,0,0,0
0,0,0,0,0,0,0,0,0,0,0,0,0
0,0,0,3,3,3,3,3,3,3,0,0,0
0,0,0,1,10,10,10,10,10,1,0,0,0
0,1,1,2,2,1,1,1,2,2,1,1,0
1,2,2,2,15,15,15,15,15,2,2,2,1
0,1,1,2,2,1,1,1,2,2,1,1,0
0,0,0,1,10,10,10,10,10,1,0,0,0
0,0,0,3,3,3,3,3,3,3,0,0,0
0,0,0,0,0,0,0,0,0,0,0,0,0
0,0,0,0,0,0,0,0,0,0,0,0,0
0,0,0,0,0,0,0,0,0,0,0,0,0
endlayer

layer
0,0,0,0,0,0,0,0,0,0,0,0,0
0,0,0,0,0,0,0,0,0,0,0,0,0
0,0,0,0,0,0,0,0,0,0,0,0,0
0,0,0,0,0,0,0,0,0,0,0,0,0
0,0,0,11,8,0,0,0,9,11,0,0,0
0,11,11,2,2,0,0,0,2,2,11,11,0
11,2,2,2,15,0,0,0,15,2,2,2,11
0,11,11,2,2,0,0,0,2,2,11,11,0
0,0,0,11,8,0,0,0,9,11,0,0,0
0,0,0,0,0,0,0,0,0,0,0,0,0
0,0,0,0,0,0,0,0,0,0,0,0,0
0,0,0,0,0,0,0,0,0,0,0,0,0
0,0,0,0,0,0,0,0,0,0,0,0,0
endlayer

layer
0,0,0,0,0,0,0,0,0,0,0,0,0
0,0,0,0,0,0,0,0,0,0,0,0,0
0,0,0,0,0,0,0,0,0,0,0,0,0
0,0,0,0,0,0,0,0,0,0,0,0,0
0,0,0,11,8,0,0,0,9,11,0,0,0
0,11,11,2,2,0,0,0,2,2,11,11,0
11,2,2,2,15,0,0,0,15,2,2,2,11
0,11,11,2,2,0,0,0,2,2,11,11,0
0,0,0,11,8,0,0,0,9,11,0,0,0
0,0,0,0,0,0,0,0,0,0,0,0,0
0,0,0,0,0,0,0,0,0,0,0,0,0
0,0,0,0,0,0,0,0,0,0,0,0,0
0,0,0,0,0,0,0,0,0,0,0,0,0
endlayer

layer
0,0,0,0,0,0,0,0,0,0,0,0,0
0,0,0,0,0,0,0,0,0,0,0,0,0
0,0,0,0,0,0,0,0,0,0,0,0,0
0,0,0,0,0,0,0,0,0,0,0,0,0
0,0,0,11,8,0,0,0,9,11,0,0,0
0,11,11,2,2,0,0,0,2,2,11,11,0
11,2,2,2,15,0,0,0,15,2,2,2,11
0,11,11,2,2,0,0,0,2,2,11,11,0
0,0,0,11,8,0,0,0,9,11,0,0,0
0,0,0,0,0,0,0,0,0,0,0,0,0
0,0,0,0,0,0,0,0,0,0,0,0,0
0,0,0,0,0,0,0,0,0,0,0,0,0
0,0,0,0,0,0,0,0,0,0,0,0,0
endlayer

layer
0,0,0,0,0,0,0,0,0,0,0,0,0
0,0,0,0,0,0,0,0,0,0,0,0,0
0,0,0,0,0,0,0,0,0,0,0,0,0
0,0,0,0,0,0,0,0,0,0,0,0,0
0,0,0,11,11,9,0,8,11,11,0,0,0
0,11,11,2,2,2,0,2,2,2,11,11,0
11,2,2,2,15,15,15,15,15,2,2,2,11
0,11,11,2,2,2,0,2,2,2,11,11,0
0,0,0,11,11,9,0,8,11,11,0,0,0
0,0,0,0,0,0,0,0,0,0,0,0,0
0,0,0,0,0,0,0,0,0,0,0,0,0
0,0,0,0,0,0,0,0,0,0,0,0,0
0,0,0,0,0,0,0,0,0,0,0,0,0
endlayer

layer
0,0,0,0,0,0,0,0,0,0,0,0,0
0,0,0,0,0,0,0,0,0,0,0,0,0
0,0,0,0,0,0,0,0,0,0,0,0,0
0,0,0,0,0,0,0,0,0,0,0,0,0
0,0,0,11,11,8,0,9,11,11,0,0,0
0,11,11,2,2,2,2,2,2,2,11,11,0
11,2,2,2,14,12,12,12,14,2,2,2,11
0,11,11,2,2,2,2,2,2,2,11,11,0
0,0,0,11,11,8,0,9,11,11,0,0,0
0,0,0,0,0,0,0,0,0,0,0,0,0
0,0,0,0,0,0,0,0,0,0,0,0,0
0,0,0,0,0,0,0,0,0,0,0,0,0
0,0,0,0,0,0,0,0,0,0,0,0,0
endlayer

layer
0,0,0,0,0,0,0,0,0,0,0,0,0
0,0,0,0,0,0,0,0,0,0,0,0,0
0,0,0,0,0,0,0,0,0,0,0,0,0
0,0,0,0,0,0,0,0,0,0,0,0,0
0,0,0,12,12,8,0,9,12,12,0,0,0
0,12,12,2,2,2,2,2,2,2,12,12,0
12,2,2,2,13,12,12,12,13,2,2,2,12
0,12,12,2,2,2,2,2,2,2,12,12,0
0,0,0,12,12,8,0,9,12,12,0,0,0
0,0,0,0,0,0,0,0,0,0,0,0,0
0,0,0,0,0,0,0,0,0,0,0,0,0
0,0,0,0,0,0,0,0,0,0,0,0,0
0,0,0,0,0,0,0,0,0,0,0,0,0
endlayer

layer
0,0,0,0,0,0,0,0,0,0,0,0,0
0,0,0,0,0,0,0,0,0,0,0,0,0
0,0,0,0,0,0,0,0,0,0,0,0,0
0,0,0,0,0,0,0,0,0,0,0,0,0
0,0,0,12,12,8,0,9,12,12,0,0,0
0,12,12,2,2,2,2,2,2,2,12,12,0
12,2,2,2,14,12,12,12,14,2,2,2,12
0,12,12,2,2,2,2,2,2,2,12,12,0
0,0,0,12,12,8,0,9,12,12,0,0,0
0,0,0,0,0,0,0,0,0,0,0,0,0
0,0,0,0,0,0,0,0,0,0,0,0,0
0,0,0,0,0,0,0,0,0,0,0,0,0
0,0,0,0,0,0,0,0,0,0,0,0,0
endlayer

layer
0,0,0,0,0,0,0,0,0,0,0,0,0
0,0,0,0,0,0,0,0,0,0,0,0,0
0,0,0,0,0,0,0,0,0,0,0,0,0
0,0,0,0,0,0,0,0,0,0,0,0,0
0,0,0,11,11,8,0,9,11,11,0,0,0
0,11,11,2,2,2,2,2,2,2,11,11,0
11,2,2,2,13,12,12,12,13,2,2,2,11
0,11,11,2,2,2,2,2,2,2,11,11,0
0,0,0,11,11,8,0,9,11,11,0,0,0
0,0,0,0,0,0,0,0,0,0,0,0,0
0,0,0,0,0,0,0,0,0,0,0,0,0
0,0,0,0,0,0,0,0,0,0,0,0,0
0,0,0,0,0,0,0,0,0,0,0,0,0
endlayer

layer
0,0,0,0,0,0,0,0,0,0,0,0,0
0,0,0,0,0,0,0,0,0,0,0,0,0
0,0,0,0,0,0,0,0,0,0,0,0,0
0,0,0,0,0,0,0,0,0,0,0,0,0
0,0,0,11,11,8,0,9,11,11,0,0,0
0,11,11,2,2,2,2,2,2,2,11,11,0
11,2,2,2,14,12,12,12,14,2,2,2,11
0,11,11,2,2,2,2,2,2,2,11,11,0
0,0,0,11,11,8,0,9,11,11,0,0,0
0,0,0,0,0,0,0,0,0,0,0,0,0
0,0,0,0,0,0,0,0,0,0,0,0,0
0,0,0,0,0,0,0,0,0,0,0,0,0
0,0,0,0,0,0,0,0,0,0,0,0,0
endlayer

layer
0,0,0,0,0,0,0,0,0,0,0,0,0
0,0,0,0,0,0,0,0,0,0,0,0,0
0,0,0,0,0,0,0,0,0,0,0,0,0
0,0,0,0,0,0,0,0,0,0,0,0,0
0,0,0,11,11,8,0,9,11,11,0,0,0
0,11,11,2,2,2,2,2,2,2,11,11,0
0,0,2,2,13,12,12,12,13,2,2,2,11
0,11,11,2,2,2,2,2,2,2,11,11,0
0,0,0,11,11,8,0,9,11,11,0,0,0
0,0,0,0,0,0,0,0,0,0,0,0,0
0,0,0,0,0,0,0,0,0,0,0,0,0
0,0,0,0,0,0,0,0,0,0,0,0,0
0,0,0,0,0,0,0,0,0,0,0,0,0
endlayer

layer
0,0,0,0,0,0,0,0,0,0,0,0,0
0,0,0,0,0,0,0,0,0,0,0,0,0
0,0,0,0,0,0,0,0,0,0,0,0,0
0,0,0,0,0,0,0,0,0,0,0,0,0
0,0,0,11,11,8,0,9,11,11,0,0,0
0,0,11,2,2,2,2,2,2,2,11,11,0
0,11,2,2,14,12,12,12,14,2,2,2,11
0,0,11,2,2,2,2,2,2,2,11,11,0
0,0,0,11,11,8,0,9,11,11,0,0,0
0,0,0,0,0,0,0,0,0,0,0,0,0
0,0,0,0,0,0,0,0,0,0,0,0,0
0,0,0,0,0,0,0,0,0,0,0,0,0
0,0,0,0,0,0,0,0,0,0,0,0,0
endlayer

layer
0,0,0,0,0,0,0,0,0,0,0,0,0
0,0,0,0,0,0,0,0,0,0,0,0,0
0,0,0,0,0,0,0,0,0,0,0,0,0
0,0,0,0,0,0,0,0,0,0,0,0,0
0,0,0,11,11,8,0,9,11,11,0,0,0
0,0,11,2,2,2,2,2,2,2,11,11,0
0,0,11,2,13,12,12,12,13,2,2,2,11
0,0,11,2,2,2,2,2,2,2,11,11,0
0,0,0,11,11,8,0,9,11,11,0,0,0
0,0,0,0,0,0,0,0,0,0,0,0,0
0,0,0,0,0,0,0,0,0,0,0,0,0
0,0,0,0,0,0,0,0,0,0,0,0,0
0,0,0,0,0,0,0,0,0,0,0,0,0
endlayer

layer
0,0,0,0,0,0,0,0,0,0,0,0,0
0,0,0,0,0,0,0,0,0,0,0,0,0
0,0,0,0,0,0,0,0,0,0,0,0,0
0,0,0,0,0,0,0,0,0,0,0,0,0
0,0,0,11,11,8,0,9,11,11,0,0,0
0,0,11,2,2,2,2,2,2,2,11,11,0
0,0,11,2,14,12,12,12,14,2,2,2,11
0,0,11,2,2,2,2,2,2,2,11,11,0
0,0,0,11,11,8,0,9,11,11,0,0,0
0,0,0,0,0,0,0,0,0,0,0,0,0
0,0,0,0,0,0,0,0,0,0,0,0,0
0,0,0,0,0,0,0,0,0,0,0,0,0
0,0,0,0,0,0,0,0,0,0,0,0,0
endlayer

layer
0,0,0,0,0,0,0,0,0,0,0,0,0
0,0,0,0,0,0,0,0,0,0,0,0,0
0,0,0,0,0,0,0,0,0,0,0,0,0
0,0,0,0,0,0,0,0,0,0,0,0,0
0,0,0,11,11,8,0,9,11,11,0,0,0
0,0,11,2,2,2,2,2,2,2,11,11,0
0,0,11,2,13,12,12,12,13,2,2,2,11
0,0,11,2,2,2,2,2,2,2,11,11,0
0,0,0,11,11,8,0,9,11,11,0,0,0
0,0,0,0,0,0,0,0,0,0,0,0,0
0,0,0,0,0,0,0,0,0,0,0,0,0
0,0,0,0,0,0,0,0,0,0,0,0,0
0,0,0,0,0,0,0,0,0,0,0,0,0
endlayer

layer
0,0,0,0,0,0,0,0,0,0,0,0,0
0,0,0,0,0,0,0,0,0,0,0,0,0
0,0,0,0,0,0,0,0,0,0,0,0,0
0,0,0,0,0,0,0,0,0,0,0,0,0
0,0,0,11,11,8,0,9,11,11,0,0,0
0,0,11,2,2,2,2,2,2,2,11,11,0
0,0,11,2,14,12,12,12,14,2,2,2,11
0,0,11,2,2,2,2,2,2,2,11,11,0
0,0,0,11,11,8,0,9,11,11,0,0,0
0,0,0,0,0,0,0,0,0,0,0,0,0
0,0,0,0,0,0,0,0,0,0,0,0,0
0,0,0,0,0,0,0,0,0,0,0,0,0
0,0,0,0,0,0,0,0,0,0,0,0,0
endlayer

layer
0,0,0,0,0,0,0,0,0,0,0,0,0
0,0,0,0,0,0,0,0,0,0,0,0,0
0,0,0,0,0,0,0,0,0,0,0,0,0
0,0,0,0,0,0,0,0,0,0,0,0,0
0,0,0,11,11,8,0,9,11,11,0,0,0
0,0,11,2,2,2,2,2,2,2,11,11,0
0,0,11,2,13,12,12,12,13,2,2,2,11
0,0,11,2,2,2,2,2,2,2,11,11,0
0,0,0,11,11,8,0,9,11,11,0,0,0
0,0,0,0,0,0,0,0,0,0,0,0,0
0,0,0,0,0,0,0,0,0,0,0,0,0
0,0,0,0,0,0,0,0,0,0,0,0,0
0,0,0,0,0,0,0,0,0,0,0,0,0
endlayer

layer
0,0,0,0,0,0,0,0,0,0,0,0,0
0,0,0,0,0,0,0,0,0,0,0,0,0
0,0,0,0,0,0,0,0,0,0,0,0,0
0,0,0,0,0,0,0,0,0,0,0,0,0
0,0,0,11,11,8,12,9,11,11,0,0,0
0,0,11,2,2,2,0,2,2,2,11,11,0
0,0,11,2,14,12,12,12,14,2,2,2,11
0,0,11,2,2,2,0,2,2,2,11,11,0
0,0,0,11,11,8,12,9,11,11,0,0,0
0,0,0,0,0,0,0,0,0,0,0,0,0
0,0,0,0,0,0,0,0,0,0,0,0,0
0,0,0,0,0,0,0,0,0,0,0,0,0
0,0,0,0,0,0,0,0,0,0,0,0,0
endlayer

layer
0,0,0,0,0,0,0,0,0,0,0,0,0
0,0,0,0,0,0,0,0,0,0,0,0,0
0,0,0,0,0,0,0,0,0,0,0,0,0
0,0,0,0,0,0,0,0,0,0,0,0,0
0,0,0,12,12,8,0,9,12,12,0,0,0
0,0,12,2,2,2,0,2,2,2,12,12,0
0,0,12,2,13,12,12,12,13,2,2,2,12
0,0,12,2,2,2,0,2,2,2,12,12,0
0,0,0,12,12,8,0,9,12,12,0,0,0
0,0,0,0,0,0,0,0,0,0,0,0,0
0,0,0,0,0,0,0,0,0,0,0,0,0
0,0,0,0,0,0,0,0,0,0,0,0,0
0,0,0,0,0,0,0,0,0,0,0,0,0
endlayer

layer
0,0,0,0,0,0,0,0,0,0,0,0,0
0,0,0,0,0,0,0,0,0,0,0,0,0
0,0,0,0,0,0,0,0,0,0,0,0,0
0,0,0,0,0,0,0,0,0,0,0,0,0
0,0,0,12,12,10,12,10,12,0,0,0,0
0,0,12,2,2,2,0,2,2,12,12,0,0
0,0,12,2,14,12,12,12,14,2,2,12,0
0,0,12,2,2,2,0,2,2,12,12,0,0
0,0,0,12,12,10,12,10,12,0,0,0,0
0,0,0,0,0,0,0,0,0,0,0,0,0
0,0,0,0,0,0,0,0,0,0,0,0,0
0,0,0,0,0,0,0,0,0,0,0,0,0
0,0,0,0,0,0,0,0,0,0,0,0,0
endlayer

layer
0,0,0,0,0,0,0,0,0,0,0,0,0
0,0,0,0,0,0,0,0,0,0,0,0,0
0,0,0,0,0,0,0,0,0,0,0,0,0
0,0,0,0,0,0,0,0,0,0,0,0,0
0,0,0,11,11,8,0,12,0,0,0,0,0
0,0,11,2,2,2,0,2,12,12,0,0,0
0,0,11,2,13,12,0,12,2,2,12,0,0
0,0,11,2,2,2,0,2,12,12,0,0,0
0,0,0,11,11,8,0,12,0,0,0,0,0
0,0,0,0,0,0,0,0,0,0,0,0,0
0,0,0,0,0,0,0,0,0,0,0,0,0
0,0,0,0,0,0,0,0,0,0,0,0,0
0,0,0,0,0,0,0,0,0,0,0,0,0
endlayer

layer
0,0,0,0,0,0,0,0,0,0,0,0,0
0,0,0,0,0,0,0,0,0,0,0,0,0
0,0,0,0,0,0,0,0,0,0,0,0,0
0,0,0,0,0,0,0,0,0,0,0,0,0
0,0,0,11,11,8,0,0,0,0,0,0,0
0,0,11,2,2,2,0,12,0,0,0,0,0
0,0,11,2,14,12,0,12,12,0,0,0,0
0,0,11,2,2,2,0,12,0,0,0,0,0
0,0,0,11,11,8,0,0,0,0,0,0,0
0,0,0,0,0,0,0,0,0,0,0,0,0
0,0,0,0,0,0,0,0,0,0,0,0,0
0,0,0,0,0,0,0,0,0,0,0,0,0
0,0,0,0,0,0,0,0,0,0,0,0,0
endlayer

layer
0,0,0,0,0,0,0,0,0,0,0,0,0
0,0,0,0,0,0,0,0,0,0,0,0,0
0,0,0,0,0,0,0,0,0,0,0,0,0
0,0,0,0,0,0,0,0,0,0,0,0,0
0,0,0,11,11,8,0,0,0,0,0,0,0
0,0,11,2,2,2,0,0,0,0,0,0,0
0,0,11,2,13,12,0,0,0,0,0,0,0
0,0,11,2,2,2,0,0,0,0,0,0,0
0,0,0,11,11,8,0,0,0,0,0,0,0
0,0,0,0,0,0,0,0,0,0,0,0,0
0,0,0,0,0,0,0,0,0,0,0,0,0
0,0,0,0,0,0,0,0,0,0,0,0,0
0,0,0,0,0,0,0,0,0,0,0,0,0
endlayer

layer
0,0,0,0,0,0,0,0,0,0,0,0,0
0,0,0,0,0,0,0,0,0,0,0,0,0
0,0,0,0,0,0,0,0,0,0,0,0,0
0,0,0,0,0,0,0,0,0,0,0,0,0
0,0,0,11,11,8,0,0,0,0,0,0,0
0,0,11,2,2,2,0,0,0,0,0,0,0
0,0,0,2,14,12,0,0,0,0,0,0,0
0,0,11,2,2,2,0,0,0,0,0,0,0
0,0,0,11,11,8,0,0,0,0,0,0,0
0,0,0,0,0,0,0,0,0,0,0,0,0
0,0,0,0,0,0,0,0,0,0,0,0,0
0,0,0,0,0,0,0,0,0,0,0,0,0
0,0,0,0,0,0,0,0,0,0,0,0,0
endlayer

layer
0,0,0,0,0,0,0,0,0,0,0,0,0
0,0,0,0,0,0,0,0,0,0,0,0,0
0,0,0,0,0,0,0,0,0,0,0,0,0
0,0,0,0,0,0,0,0,0,0,0,0,0
0,0,0,11,11,8,0,0,0,0,0,0,0
0,0,11,2,2,2,0,0,0,0,0,0,0
0,11,2,2,13,12,0,0,0,0,0,0,0
0,0,11,2,2,2,0,0,0,0,0,0,0
0,0,0,11,11,8,0,0,0,0,0,0,0
0,0,0,0,0,0,0,0,0,0,0,0,0
0,0,0,0,0,0,0,0,0,0,0,0,0
0,0,0,0,0,0,0,0,0,0,0,0,0
0,0,0,0,0,0,0,0,0,0,0,0,0
endlayer

layer
0,0,0,0,0,0,0,0,0,0,0,0,0
0,0,0,0,0,0,0,0,0,0,0,0,0
0,0,0,0,0,0,0,0,0,0,0,0,0
0,0,0,0,0,0,0,0,0,0,0,0,0
0,0,0,11,11,8,0,0,0,0,0,0,0
0,0,11,2,2,2,0,0,0,0,0,0,0
0,11,2,2,14,12,0,0,0,0,0,0,0
0,0,11,2,2,2,0,0,0,0,0,0,0
0,0,0,11,11,8,0,0,0,0,0,0,0
0,0,0,0,0,0,0,0,0,0,0,0,0
0,0,0,0,0,0,0,0,0,0,0,0,0
0,0,0,0,0,0,0,0,0,0,0,0,0
0,0,0,0,0,0,0,0,0,0,0,0,0
endlayer

layer
0,0,0,0,0,0,0,0,0,0,0,0,0
0,0,0,0,0,0,0,0,0,0,0,0,0
0,0,0,0,0,0,0,0,0,0,0,0,0
0,0,0,0,0,0,0,0,0,0,0,0,0
0,0,0,11,11,8,0,0,0,0,0,0,0
0,0,11,2,2,2,0,0,0,0,0,0,0
0,11,2,2,13,12,0,0,0,0,0,0,0
0,0,11,2,2,2,0,0,0,0,0,0,0
0,0,0,11,11,8,0,0,0,0,0,0,0
0,0,0,0,0,0,0,0,0,0,0,0,0
0,0,0,0,0,0,0,0,0,0,0,0,0
0,0,0,0,0,0,0,0,0,0,0,0,0
0,0,0,0,0,0,0,0,0,0,0,0,0
endlayer

layer
0,0,0,0,0,0,0,0,0,0,0,0,0
0,0,0,0,0,0,0,0,0,0,0,0,0
0,0,0,0,0,0,0,0,0,0,0,0,0
0,0,0,0,0,0,0,0,0,0,0,0,0
0,0,0,11,11,8,0,0,0,0,0,0,0
0,0,11,2,2,2,0,0,0,0,0,0,0
0,11,2,2,14,12,0,0,0,0,0,0,0
0,0,11,2,2,2,0,0,0,0,0,0,0
0,0,0,11,11,8,0,0,0,0,0,0,0
0,0,0,0,0,0,0,0,0,0,0,0,0
0,0,0,0,0,0,0,0,0,0,0,0,0
0,0,0,0,0,0,0,0,0,0,0,0,0
0,0,0,0,0,0,0,0,0,0,0,0,0
endlayer

layer
0,0,0,0,0,0,0,0,0,0,0,0,0
0,0,0,0,0,0,0,0,0,0,0,0,0
0,0,0,0,0,0,0,0,0,0,0,0,0
0,0,0,0,0,0,0,0,0,0,0,0,0
0,0,0,11,11,8,0,0,0,0,0,0,0
0,0,11,2,2,2,0,0,0,0,0,0,0
0,12,2,2,13,12,0,0,0,0,0,0,0
0,0,11,2,2,2,0,0,0,0,0,0,0
0,0,0,11,11,8,0,0,0,0,0,0,0
0,0,0,0,0,0,0,0,0,0,0,0,0
0,0,0,0,0,0,0,0,0,0,0,0,0
0,0,0,0,0,0,0,0,0,0,0,0,0
0,0,0,0,0,0,0,0,0,0,0,0,0
endlayer

layer
0,0,0,0,0,0,0,0,0,0,0,0,0
0,0,0,0,0,0,0,0,0,0,0,0,0
0,0,0,0,0,0,0,0,0,0,0,0,0
0,0,0,0,0,0,0,0,0,0,0,0,0
0,0,0,11,11,8,0,0,0,0,0,0,0
0,0,12,2,2,2,0,0,0,0,0,0,0
0,0,2,2,14,12,0,0,0,0,0,0,0
0,0,12,2,2,2,0,0,0,0,0,0,0
0,0,0,11,11,8,0,0,0,0,0,0,0
0,0,0,0,0,0,0,0,0,0,0,0,0
0,0,0,0,0,0,0,0,0,0,0,0,0
0,0,0,0,0,0,0,0,0,0,0,0,0
0,0,0,0,0,0,0,0,0,0,0,0,0
endlayer

layer
0,0,0,0,0,0,0,0,0,0,0,0,0
0,0,0,0,0,0,0,0,0,0,0,0,0
0,0,0,0,0,0,0,0,0,0,0,0,0
0,0,0,0,0,0,0,0,0,0,0,0,0
0,0,0,12,12,8,0,0,0,0,0,0,0
0,0,0,2,2,2,0,0,0,0,0,0,0
0,0,12,2,13,12,0,0,0,0,0,0,0
0,0,0,2,2,2,0,0,0,0,0,0,0
0,0,0,12,12,8,0,0,0,0,0,0,0
0,0,0,0,0,0,0,0,0,0,0,0,0
0,0,0,0,0,0,0,0,0,0,0,0,0
0,0,0,0,0,0,0,0,0,0,0,0,0
0,0,0,0,0,0,0,0,0,0,0,0,0
endlayer

layer
0,0,0,0,0,0,0,0,0,0,0,0,0
0,0,0,0,0,0,0,0,0,0,0,0,0
0,0,0,0,0,0,0,0,0,0,0,0,0
0,0,0,0,0,0,0,0,0,0,0,0,0
0,0,0,0,12,12,0,0,0,0,0,0,0
0,0,0,12,2,12,0,0,0,0,0,0,0
0,0,12,2,14,12,0,0,0,0,0,0,0
0,0,0,12,2,12,0,0,0,0,0,0,0
0,0,0,0,12,12,0,0,0,0,0,0,0
0,0,0,0,0,0,0,0,0,0,0,0,0
0,0,0,0,0,0,0,0,0,0,0,0,0
0,0,0,0,0,0,0,0,0,0,0,0,0
0,0,0,0,0,0,0,0,0,0,0,0,0
endlayer

layer
0,0,0,0,0,0,0,0,0,0,0,0,0
0,0,0,0,0,0,0,0,0,0,0,0,0
0,0,0,0,0,0,0,0,0,0,0,0,0
0,0,0,0,0,0,0,0,0,0,0,0,0
0,0,0,0,0,0,0,0,0,0,0,0,0
0,0,0,12,12,12,0,0,0,0,0,0,0
0,0,0,2,0,12,0,0,0,0,0,0,0
0,0,0,12,12,12,0,0,0,0,0,0,0
0,0,0,0,0,0,0,0,0,0,0,0,0
0,0,0,0,0,0,0,0,0,0,0,0,0
0,0,0,0,0,0,0,0,0,0,0,0,0
0,0,0,0,0,0,0,0,0,0,0,0,0
0,0,0,0,0,0,0,0,0,0,0,0,0
endlayer


layer
0,0,0,0,0,0,0,0,0,0,0,0,0
0,0,0,0,0,0,0,0,0,0,0,0,0
0,0,0,0,0,0,0,0,0,0,0,0,0
0,0,0,0,0,0,0,0,0,0,0,0,0
0,0,0,0,0,0,0,0,0,0,0,0,0
0,0,0,0,12,12,0,0,0,0,0,0,0
0,0,0,12,2,0,0,0,0,0,0,0,0
0,0,0,0,12,12,0,0,0,0,0,0,0
0,0,0,0,0,0,0,0,0,0,0,0,0
0,0,0,0,0,0,0,0,0,0,0,0,0
0,0,0,0,0,0,0,0,0,0,0,0,0
0,0,0,0,0,0,0,0,0,0,0,0,0
0,0,0,0,0,0,0,0,0,0,0,0,0
endlayer

layer
0,0,0,0,0,0,0,0,0,0,0,0,0
0,0,0,0,0,0,0,0,0,0,0,0,0
0,0,0,0,0,0,0,0,0,0,0,0,0
0,0,0,0,0,0,0,0,0,0,0,0,0
0,0,0,0,0,0,0,0,0,0,0,0,0
0,0,0,0,0,12,0,0,0,0,0,0,0
0,0,0,0,12,0,0,0,0,0,0,0,0
0,0,0,0,0,12,0,0,0,0,0,0,0
0,0,0,0,0,0,0,0,0,0,0,0,0
0,0,0,0,0,0,0,0,0,0,0,0,0
0,0,0,0,0,0,0,0,0,0,0,0,0
0,0,0,0,0,0,0,0,0,0,0,0,0
0,0,0,0,0,0,0,0,0,0,0,0,0
endlayer

layer
0,0,0,0,0,0,0,0,0,0,0,0,0
0,0,0,0,0,0,0,0,0,0,0,0,0
0,0,0,0,0,0,0,0,0,0,0,0,0
0,0,0,0,0,0,0,0,0,0,0,0,0
0,0,0,0,0,0,0,0,0,0,0,0,0
0,0,0,0,0,0,0,0,0,0,0,0,0
0,0,0,0,0,12,0,0,0,0,0,0,0
0,0,0,0,0,0,0,0,0,0,0,0,0
0,0,0,0,0,0,0,0,0,0,0,0,0
0,0,0,0,0,0,0,0,0,0,0,0,0
0,0,0,0,0,0,0,0,0,0,0,0,0
0,0,0,0,0,0,0,0,0,0,0,0,0
0,0,0,0,0,0,0,0,0,0,0,0,0
endlayer

